Workbook

Sheet 1_输入与假设
B2: Google 估值锚定模型 · 输入区（方案 A：基本面 / 倍数维度分离）
B3: 蓝色 = 你输入；黑色 = 自动计算；绿色 = 决策结果
B5: 一、当前市场数据
B7: 当前股价 ($) | C7: 395 | D7: 当前 GOOGL 股价 | G7: 2026/05/08 实时（GOOGL）
B8: 流通股本 (B 股) | C8: 12.116 | D8: Class A + B + C 合计 | G8: 10-Q Q1 2026 封面（截至 2026/04/22）
B9: 当前市值 ($B) | C9: =C7*C8 -> 4785.82 | D9: 自动计算 | G9: 自动 = C7 × C8
B10: 折现率 (WACC) | C10: 0.1 | D10: 默认 10% | G10: 行业惯例（折现率默认 10%）
B11: 当前股息率 | C11: 0.0023 | D11: 默认 0.23% | G11: Q1 2026 季报披露
B12: 年度净回购率 | C12: 0.02 | D12: 净回购率（扣除 SBC）；管理层信心信号 | G12: 每季度核对：实际回购 ÷ 当季初市值 × 4
B13: 二、2025 年业务线营收基线
G14: 数据来源 / 时间戳
B15: 业务线 | C15: 2025 营收 ($B) | D15: 说明 | G15: 数据来源 / 验证依据
B16: Search 传统广告 | C16: 200 | D16: 反垄断 + ChatGPT 蚕食长尾 | G16: 10-K 2025 / Q1 2026 10-Q / 文档 v1
B17: Search AI 增量 | C17: 26 | D17: AI Overview 25%广告化 + AI Mode 75M DAU | G17: 10-K 2025 / Q1 2026 10-Q / 文档 v1
B18: YouTube ads | C18: 40 | D18: Q4 2025 +9%；广告主迁移 | G18: 10-K 2025 / Q1 2026 10-Q / 文档 v1
B19: Google Network | C19: 28 | D19: AdSense/AdMob; Q1 2026 -4% | G19: 10-K 2025 / Q1 2026 10-Q / 文档 v1
B20: Subscriptions/Platforms/Devices | C20: 47 | D20: YT Subs/Pixel/Play/Workspace 消费 | G20: 10-K 2025 / Q1 2026 10-Q / 文档 v1
B21: Google Cloud 传统 GCP | C21: 34.5 | D21: 基础设施 + 数据库 + 应用 | G21: 10-K 2025 / Q1 2026 10-Q / 文档 v1
B22: Cloud AI | C22: 23.5 | D22: Vertex/TPU/AI Svc/3P 托管 +800% YoY | G22: 10-K 2025 / Q1 2026 10-Q / 文档 v1
B23: Other Bets | C23: 2 | D23: Calico + X labs（Waymo 期权另算） | G23: 10-K 2025 / Q1 2026 10-Q / 文档 v1
B24: 合计 | C24: 401 | D24: vs Alphabet 实际 2025 $402.8B
B25: 三、三情景 CAGR 假设（基本面维度）— 唯一情景间变化
B27: 业务线 | C27: Bear CAGR | D27: Base CAGR | E27: Bull CAGR | F27: 说明 | G27: 数据 / 逻辑来源
B28: Search 传统广告 | C28: 0.03 | D28: 0.05 | E28: 0.07 | F28: 反垄断 + ChatGPT 蚕食长尾 | G28: Q1 2026 数据 + 文档 bottom-up
B29: Search AI 增量 | C29: 0.3 | D29: 0.4 | E29: 0.55 | F29: AI Overview 25%广告化 + AI Mode 75M DAU | G29: Q1 2026 数据 + 文档 bottom-up
B30: YouTube ads | C30: 0.06 | D30: 0.1 | E30: 0.14 | F30: Q4 2025 +9%；广告主迁移 | G30: Q1 2026 数据 + 文档 bottom-up
B31: Google Network | C31: -0.03 | D31: -0.01 | E31: 0.02 | F31: AdSense/AdMob; Q1 2026 -4% | G31: Q1 2026 数据 + 文档 bottom-up
B32: Subscriptions/Platforms/Devices | C32: 0.1 | D32: 0.15 | E32: 0.2 | F32: YT Subs/Pixel/Play/Workspace 消费 | G32: Q1 2026 数据 + 文档 bottom-up
B33: Google Cloud 传统 GCP | C33: 0.08 | D33: 0.12 | E33: 0.16 | F33: 基础设施 + 数据库 + 应用 | G33: Q1 2026 数据 + 文档 bottom-up
B34: Cloud AI | C34: 0.3 | D34: 0.4 | E34: 0.5 | F34: Vertex/TPU/AI Svc/3P 托管 +800% YoY | G34: Q1 2026 数据 + 文档 bottom-up
B35: Other Bets | C35: 0.3 | D35: 0.5 | E35: 0.8 | F35: Calico + X labs（Waymo 期权另算） | G35: Q1 2026 数据 + 文档 bottom-up
B36: 四、2030 长期均值倍数（市场情绪维度，跨情景固定）
B37: 原理：倍数是市场情绪/利率/风险偏好的函数，与业务情景独立。三情景下倍数相同。
B38: 业务线 | C38: 基准倍数 (P/Sales) | D38: 历史区间 | E38: 可比公司参考
B39: Search 传统广告 | C39: 5 | D39: 4-6x | E39: 成熟广告
B40: Search AI 增量 | C40: 8 | D40: 7-10x | E40: 高增速广告
B41: YouTube ads | C41: 5.5 | D41: 4-7x | E41: NFLX 6x
B42: Google Network | C42: 3.5 | D42: 3-5x | E42: 萎缩业务
B43: Subscriptions/Platforms/Devices | C43: 6 | D43: 5-8x | E43: SaaS 溢价
B44: Google Cloud 传统 GCP | C44: 5 | D44: 5-7x | E44: AWS 对标
...

Sheet 2_5年预测
B2: Google 5 年三情景营收预测 (2025 → 2030)
B3: 基于 Sheet 1 输入自动计算 — 你不需要修改这里
B5: Bear 情景
B7: 业务线 | C7: 2025 | D7: 2026 | E7: 2027 | F7: 2028 | G7: 2029 | H7: 2030
B8: Search 传统广告 | C8: ='1_输入与假设'!C16 -> 200 | D8: =C8*(1+'1_输入与假设'!C28)^1 -> 206 | E8: =C8*(1+'1_输入与假设'!C28)^2 -> 212.18 | F8: =C8*(1+'1_输入与假设'!C28)^3 -> 218.5454 | G8: =C8*(1+'1_输入与假设'!C28)^4 -> 225.10176 | H8: =C8*(1+'1_输入与假设'!C28)^5 -> 231.85481
B9: Search AI 增量 | C9: ='1_输入与假设'!C17 -> 26 | D9: =C9*(1+'1_输入与假设'!C29)^1 -> 33.8 | E9: =C9*(1+'1_输入与假设'!C29)^2 -> 43.94 | F9: =C9*(1+'1_输入与假设'!C29)^3 -> 57.122 | G9: =C9*(1+'1_输入与假设'!C29)^4 -> 74.2586 | H9: =C9*(1+'1_输入与假设'!C29)^5 -> 96.53618
B10: YouTube ads | C10: ='1_输入与假设'!C18 -> 40 | D10: =C10*(1+'1_输入与假设'!C30)^1 -> 42.4 | E10: =C10*(1+'1_输入与假设'!C30)^2 -> 44.944 | F10: =C10*(1+'1_输入与假设'!C30)^3 -> 47.64064 | G10: =C10*(1+'1_输入与假设'!C30)^4 -> 50.499078 | H10: =C10*(1+'1_输入与假设'!C30)^5 -> 53.529023
B11: Google Network | C11: ='1_输入与假设'!C19 -> 28 | D11: =C11*(1+'1_输入与假设'!C31)^1 -> 27.16 | E11: =C11*(1+'1_输入与假设'!C31)^2 -> 26.3452 | F11: =C11*(1+'1_输入与假设'!C31)^3 -> 25.554844 | G11: =C11*(1+'1_输入与假设'!C31)^4 -> 24.788199 | H11: =C11*(1+'1_输入与假设'!C31)^5 -> 24.044553
B12: Subscriptions/Platforms/Devices | C12: ='1_输入与假设'!C20 -> 47 | D12: =C12*(1+'1_输入与假设'!C32)^1 -> 51.7 | E12: =C12*(1+'1_输入与假设'!C32)^2 -> 56.87 | F12: =C12*(1+'1_输入与假设'!C32)^3 -> 62.557 | G12: =C12*(1+'1_输入与假设'!C32)^4 -> 68.8127 | H12: =C12*(1+'1_输入与假设'!C32)^5 -> 75.69397
B13: Google Cloud 传统 GCP | C13: ='1_输入与假设'!C21 -> 34.5 | D13: =C13*(1+'1_输入与假设'!C33)^1 -> 37.26 | E13: =C13*(1+'1_输入与假设'!C33)^2 -> 40.2408 | F13: =C13*(1+'1_输入与假设'!C33)^3 -> 43.460064 | G13: =C13*(1+'1_输入与假设'!C33)^4 -> 46.936869 | H13: =C13*(1+'1_输入与假设'!C33)^5 -> 50.691819
B14: Cloud AI | C14: ='1_输入与假设'!C22 -> 23.5 | D14: =C14*(1+'1_输入与假设'!C34)^1 -> 30.55 | E14: =C14*(1+'1_输入与假设'!C34)^2 -> 39.715 | F14: =C14*(1+'1_输入与假设'!C34)^3 -> 51.6295 | G14: =C14*(1+'1_输入与假设'!C34)^4 -> 67.11835 | H14: =C14*(1+'1_输入与假设'!C34)^5 -> 87.253855
B15: Other Bets | C15: ='1_输入与假设'!C23 -> 2 | D15: =C15*(1+'1_输入与假设'!C35)^1 -> 2.6 | E15: =C15*(1+'1_输入与假设'!C35)^2 -> 3.38 | F15: =C15*(1+'1_输入与假设'!C35)^3 -> 4.394 | G15: =C15*(1+'1_输入与假设'!C35)^4 -> 5.7122 | H15: =C15*(1+'1_输入与假设'!C35)^5 -> 7.42586
B16: Bear 总营收 | C16: =SUM(C8:C15) -> 401 | D16: =SUM(D8:D15) -> 431.47 | E16: =SUM(E8:E15) -> 467.615 | F16: =SUM(F8:F15) -> 510.90345 | G16: =SUM(G8:G15) -> 563.22776 | H16: =SUM(H8:H15) -> 627.03007
B18: Base 情景
B20: 业务线 | C20: 2025 | D20: 2026 | E20: 2027 | F20: 2028 | G20: 2029 | H20: 2030
B21: Search 传统广告 | C21: ='1_输入与假设'!C16 -> 200 | D21: =C21*(1+'1_输入与假设'!D28)^1 -> 210 | E21: =C21*(1+'1_输入与假设'!D28)^2 -> 220.5 | F21: =C21*(1+'1_输入与假设'!D28)^3 -> 231.525 | G21: =C21*(1+'1_输入与假设'!D28)^4 -> 243.10125 | H21: =C21*(1+'1_输入与假设'!D28)^5 -> 255.25631
B22: Search AI 增量 | C22: ='1_输入与假设'!C17 -> 26 | D22: =C22*(1+'1_输入与假设'!D29)^1 -> 36.4 | E22: =C22*(1+'1_输入与假设'!D29)^2 -> 50.96 | F22: =C22*(1+'1_输入与假设'!D29)^3 -> 71.344 | G22: =C22*(1+'1_输入与假设'!D29)^4 -> 99.8816 | H22: =C22*(1+'1_输入与假设'!D29)^5 -> 139.83424
B23: YouTube ads | C23: ='1_输入与假设'!C18 -> 40 | D23: =C23*(1+'1_输入与假设'!D30)^1 -> 44 | E23: =C23*(1+'1_输入与假设'!D30)^2 -> 48.4 | F23: =C23*(1+'1_输入与假设'!D30)^3 -> 53.24 | G23: =C23*(1+'1_输入与假设'!D30)^4 -> 58.564 | H23: =C23*(1+'1_输入与假设'!D30)^5 -> 64.4204
B24: Google Network | C24: ='1_输入与假设'!C19 -> 28 | D24: =C24*(1+'1_输入与假设'!D31)^1 -> 27.72 | E24: =C24*(1+'1_输入与假设'!D31)^2 -> 27.4428 | F24: =C24*(1+'1_输入与假设'!D31)^3 -> 27.168372 | G24: =C24*(1+'1_输入与假设'!D31)^4 -> 26.896688 | H24: =C24*(1+'1_输入与假设'!D31)^5 -> 26.627721
B25: Subscriptions/Platforms/Devices | C25: ='1_输入与假设'!C20 -> 47 | D25: =C25*(1+'1_输入与假设'!D32)^1 -> 54.05 | E25: =C25*(1+'1_输入与假设'!D32)^2 -> 62.1575 | F25: =C25*(1+'1_输入与假设'!D32)^3 -> 71.481125 | G25: =C25*(1+'1_输入与假设'!D32)^4 -> 82.203294 | H25: =C25*(1+'1_输入与假设'!D32)^5 -> 94.533788
B26: Google Cloud 传统 GCP | C26: ='1_输入与假设'!C21 -> 34.5 | D26: =C26*(1+'1_输入与假设'!D33)^1 -> 38.64 | E26: =C26*(1+'1_输入与假设'!D33)^2 -> 43.2768 | F26: =C26*(1+'1_输入与假设'!D33)^3 -> 48.470016 | G26: =C26*(1+'1_输入与假设'!D33)^4 -> 54.286418 | H26: =C26*(1+'1_输入与假设'!D33)^5 -> 60.800788
B27: Cloud AI | C27: ='1_输入与假设'!C22 -> 23.5 | D27: =C27*(1+'1_输入与假设'!D34)^1 -> 32.9 | E27: =C27*(1+'1_输入与假设'!D34)^2 -> 46.06 | F27: =C27*(1+'1_输入与假设'!D34)^3 -> 64.484 | G27: =C27*(1+'1_输入与假设'!D34)^4 -> 90.2776 | H27: =C27*(1+'1_输入与假设'!D34)^5 -> 126.38864
B28: Other Bets | C28: ='1_输入与假设'!C23 -> 2 | D28: =C28*(1+'1_输入与假设'!D35)^1 -> 3 | E28: =C28*(1+'1_输入与假设'!D35)^2 -> 4.5 | F28: =C28*(1+'1_输入与假设'!D35)^3 -> 6.75 | G28: =C28*(1+'1_输入与假设'!D35)^4 -> 10.125 | H28: =C28*(1+'1_输入与假设'!D35)^5 -> 15.1875
B29: Base 总营收 | C29: =SUM(C21:C28) -> 401 | D29: =SUM(D21:D28) -> 446.71 | E29: =SUM(E21:E28) -> 503.2971 | F29: =SUM(F21:F28) -> 574.46251 | G29: =SUM(G21:G28) -> 665.33585 | H29: =SUM(H21:H28) -> 783.04939
B31: Bull 情景
B33: 业务线 | C33: 2025 | D33: 2026 | E33: 2027 | F33: 2028 | G33: 2029 | H33: 2030
B34: Search 传统广告 | C34: ='1_输入与假设'!C16 -> 200 | D34: =C34*(1+'1_输入与假设'!E28)^1 -> 214 | E34: =C34*(1+'1_输入与假设'!E28)^2 -> 228.98 | F34: =C34*(1+'1_输入与假设'!E28)^3 -> 245.0086 | G34: =C34*(1+'1_输入与假设'!E28)^4 -> 262.1592 | H34: =C34*(1+'1_输入与假设'!E28)^5 -> 280.51035
B35: Search AI 增量 | C35: ='1_输入与假设'!C17 -> 26 | D35: =C35*(1+'1_输入与假设'!E29)^1 -> 40.3 | E35: =C35*(1+'1_输入与假设'!E29)^2 -> 62.465 | F35: =C35*(1+'1_输入与假设'!E29)^3 -> 96.82075 | G35: =C35*(1+'1_输入与假设'!E29)^4 -> 150.07216 | H35: =C35*(1+'1_输入与假设'!E29)^5 -> 232.61185
B36: YouTube ads | C36: ='1_输入与假设'!C18 -> 40 | D36: =C36*(1+'1_输入与假设'!E30)^1 -> 45.6 | E36: =C36*(1+'1_输入与假设'!E30)^2 -> 51.984 | F36: =C36*(1+'1_输入与假设'!E30)^3 -> 59.26176 | G36: =C36*(1+'1_输入与假设'!E30)^4 -> 67.558406 | H36: =C36*(1+'1_输入与假设'!E30)^5 -> 77.016583
B37: Google Network | C37: ='1_输入与假设'!C19 -> 28 | D37: =C37*(1+'1_输入与假设'!E31)^1 -> 28.56 | E37: =C37*(1+'1_输入与假设'!E31)^2 -> 29.1312 | F37: =C37*(1+'1_输入与假设'!E31)^3 -> 29.713824 | G37: =C37*(1+'1_输入与假设'!E31)^4 -> 30.3081 | H37: =C37*(1+'1_输入与假设'!E31)^5 -> 30.914262
B38: Subscriptions/Platforms/Devices | C38: ='1_输入与假设'!C20 -> 47 | D38: =C38*(1+'1_输入与假设'!E32)^1 -> 56.4 | E38: =C38*(1+'1_输入与假设'!E32)^2 -> 67.68 | F38: =C38*(1+'1_输入与假设'!E32)^3 -> 81.216 | G38: =C38*(1+'1_输入与假设'!E32)^4 -> 97.4592 | H38: =C38*(1+'1_输入与假设'!E32)^5 -> 116.95104
B39: Google Cloud 传统 GCP | C39: ='1_输入与假设'!C21 -> 34.5 | D39: =C39*(1+'1_输入与假设'!E33)^1 -> 40.02 | E39: =C39*(1+'1_输入与假设'!E33)^2 -> 46.4232 | F39: =C39*(1+'1_输入与假设'!E33)^3 -> 53.850912 | G39: =C39*(1+'1_输入与假设'!E33)^4 -> 62.467058 | H39: =C39*(1+'1_输入与假设'!E33)^5 -> 72.461787
B40: Cloud AI | C40: ='1_输入与假设'!C22 -> 23.5 | D40: =C40*(1+'1_输入与假设'!E34)^1 -> 35.25 | E40: =C40*(1+'1_输入与假设'!E34)^2 -> 52.875 | F40: =C40*(1+'1_输入与假设'!E34)^3 -> 79.3125 | G40: =C40*(1+'1_输入与假设'!E34)^4 -> 118.96875 | H40: =C40*(1+'1_输入与假设'!E34)^5 -> 178.45312
B41: Other Bets | C41: ='1_输入与假设'!C23 -> 2 | D41: =C41*(1+'1_输入与假设'!E35)^1 -> 3.6 | E41: =C41*(1+'1_输入与假设'!E35)^2 -> 6.48 | F41: =C41*(1+'1_输入与假设'!E35)^3 -> 11.664 | G41: =C41*(1+'1_输入与假设'!E35)^4 -> 20.9952 | H41: =C41*(1+'1_输入与假设'!E35)^5 -> 37.79136
B42: Bull 总营收 | C42: =SUM(C34:C41) -> 401 | D42: =SUM(D34:D41) -> 463.73 | E42: =SUM(E34:E41) -> 546.0184 | F42: =SUM(F34:F41) -> 656.84835 | G42: =SUM(G34:G41) -> 809.98808 | H42: =SUM(H34:H41) -> 1026.7104

Sheet 3_SOTP估值
B2: SOTP 三情景估值（v4.0：8 业务线 + 期权组合）
B3: 三情景只让 CAGR 变化；倍数固定（市场情绪独立维度，见下方敏感性）
B5: Bear 情景 SOTP
B7: 业务线 | C7: 2030 营收 | D7: 倍数 | E7: 2030 EV | F7: 折现回 2026
B8: Search 传统广告 | C8: ='2_5年预测'!H8 -> 231.85481 | D8: ='1_输入与假设'!C39 -> 5 | E8: =C8*D8 -> 1159.2741 | F8: =E8/(1+'1_输入与假设'!C10)^4 -> 791.79979
B9: Search AI 增量 | C9: ='2_5年预测'!H9 -> 96.53618 | D9: ='1_输入与假设'!C40 -> 8 | E9: =C9*D9 -> 772.28944 | F9: =E9/(1+'1_输入与假设'!C10)^4 -> 527.48408
B10: YouTube ads | C10: ='2_5年预测'!H10 -> 53.529023 | D10: ='1_输入与假设'!C41 -> 5.5 | E10: =C10*D10 -> 294.40963 | F10: =E10/(1+'1_输入与假设'!C10)^4 -> 201.08574
B11: Google Network | C11: ='2_5年预测'!H11 -> 24.044553 | D11: ='1_输入与假设'!C42 -> 3.5 | E11: =C11*D11 -> 84.155935 | F11: =E11/(1+'1_输入与假设'!C10)^4 -> 57.479636
B12: Subscriptions/Platforms/Devices | C12: ='2_5年预测'!H12 -> 75.69397 | D12: ='1_输入与假设'!C43 -> 6 | E12: =C12*D12 -> 454.16382 | F12: =E12/(1+'1_输入与假设'!C10)^4 -> 310.2
B13: Google Cloud 传统 GCP | C13: ='2_5年预测'!H13 -> 50.691819 | D13: ='1_输入与假设'!C44 -> 5 | E13: =C13*D13 -> 253.45909 | F13: =E13/(1+'1_输入与假设'!C10)^4 -> 173.11597
B14: Cloud AI | C14: ='2_5年预测'!H14 -> 87.253855 | D14: ='1_输入与假设'!C45 -> 12 | E14: =C14*D14 -> 1047.0463 | F14: =E14/(1+'1_输入与假设'!C10)^4 -> 715.14668
B15: Other Bets | C15: ='2_5年预测'!H15 -> 7.42586 | D15: ='1_输入与假设'!C46 -> 5 | E15: =C15*D15 -> 37.1293 | F15: =E15/(1+'1_输入与假设'!C10)^4 -> 25.359811
B16: Bear 加和 | E16: =SUM(E8:E15) -> 4101.9275 | F16: =SUM(F8:F15) -> 2801.6717
B18: Base 情景 SOTP
B20: 业务线 | C20: 2030 营收 | D20: 倍数 | E20: 2030 EV | F20: 折现回 2026
B21: Search 传统广告 | C21: ='2_5年预测'!H21 -> 255.25631 | D21: ='1_输入与假设'!C39 -> 5 | E21: =C21*D21 -> 1276.2816 | F21: =E21/(1+'1_输入与假设'!C10)^4 -> 871.71748
B22: Search AI 增量 | C22: ='2_5年预测'!H22 -> 139.83424 | D22: ='1_输入与假设'!C40 -> 8 | E22: =C22*D22 -> 1118.6739 | F22: =E22/(1+'1_输入与假设'!C10)^4 -> 764.06934
B23: YouTube ads | C23: ='2_5年预测'!H23 -> 64.4204 | D23: ='1_输入与假设'!C41 -> 5.5 | E23: =C23*D23 -> 354.3122 | F23: =E23/(1+'1_输入与假设'!C10)^4 -> 242
B24: Google Network | C24: ='2_5年预测'!H24 -> 26.627721 | D24: ='1_输入与假设'!C42 -> 3.5 | E24: =C24*D24 -> 93.197025 | F24: =E24/(1+'1_输入与假设'!C10)^4 -> 63.654822
B25: Subscriptions/Platforms/Devices | C25: ='2_5年预测'!H25 -> 94.533788 | D25: ='1_输入与假设'!C43 -> 6 | E25: =C25*D25 -> 567.20273 | F25: =E25/(1+'1_输入与假设'!C10)^4 -> 387.40709
B26: Google Cloud 传统 GCP | C26: ='2_5年预测'!H26 -> 60.800788 | D26: ='1_输入与假设'!C44 -> 5 | E26: =C26*D26 -> 304.00394 | F26: =E26/(1+'1_输入与假设'!C10)^4 -> 207.63878
B27: Cloud AI | C27: ='2_5年预测'!H27 -> 126.38864 | D27: ='1_输入与假设'!C45 -> 12 | E27: =C27*D27 -> 1516.6637 | F27: =E27/(1+'1_输入与假设'!C10)^4 -> 1035.9017
B28: Other Bets | C28: ='2_5年预测'!H28 -> 15.1875 | D28: ='1_输入与假设'!C46 -> 5 | E28: =C28*D28 -> 75.9375 | F28: =E28/(1+'1_输入与假设'!C10)^4 -> 51.866334
B29: Base 加和 | E29: =SUM(E21:E28) -> 5306.2726 | F29: =SUM(F21:F28) -> 3624.2556
B31: Bull 情景 SOTP
B33: 业务线 | C33: 2030 营收 | D33: 倍数 | E33: 2030 EV | F33: 折现回 2026
B34: Search 传统广告 | C34: ='2_5年预测'!H34 -> 280.51035 | D34: ='1_输入与假设'!C39 -> 5 | E34: =C34*D34 -> 1402.5517 | F34: =E34/(1+'1_输入与假设'!C10)^4 -> 957.9617
B35: Search AI 增量 | C35: ='2_5年预测'!H35 -> 232.61185 | D35: ='1_输入与假设'!C40 -> 8 | E35: =C35*D35 -> 1860.8948 | F35: =E35/(1+'1_输入与假设'!C10)^4 -> 1271.0162
B36: YouTube ads | C36: ='2_5年预测'!H36 -> 77.016583 | D36: ='1_输入与假设'!C41 -> 5.5 | E36: =C36*D36 -> 423.59121 | F36: =E36/(1+'1_输入与假设'!C10)^4 -> 289.31849
B37: Google Network | C37: ='2_5年预测'!H37 -> 30.914262 | D37: ='1_输入与假设'!C42 -> 3.5 | E37: =C37*D37 -> 108.19992 | F37: =E37/(1+'1_输入与假设'!C10)^4 -> 73.902
B38: Subscriptions/Platforms/Devices | C38: ='2_5年预测'!H38 -> 116.95104 | D38: ='1_输入与假设'!C43 -> 6 | E38: =C38*D38 -> 701.70624 | F38: =E38/(1+'1_输入与假设'!C10)^4 -> 479.2748
B39: Google Cloud 传统 GCP | C39: ='2_5年预测'!H39 -> 72.461787 | D39: ='1_输入与假设'!C44 -> 5 | E39: =C39*D39 -> 362.30894 | F39: =E39/(1+'1_输入与假设'!C10)^4 -> 247.46188
B40: Cloud AI | C40: ='2_5年预测'!H40 -> 178.45312 | D40: ='1_输入与假设'!C45 -> 12 | E40: =C40*D40 -> 2141.4375 | F40: =E40/(1+'1_输入与假设'!C10)^4 -> 1462.6306
B41: Other Bets | C41: ='2_5年预测'!H41 -> 37.79136 | D41: ='1_输入与假设'!C46 -> 5 | E41: =C41*D41 -> 188.9568 | F41: =E41/(1+'1_输入与假设'!C10)^4 -> 129.06004
B42: Bull 加和 | E42: =SUM(E34:E41) -> 7189.6471 | F42: =SUM(F34:F41) -> 4910.6257
B44: ⭐ 基准加权公允价值（基本面维度）
B46: 情景 | C46: 概率 | D46: 2030 EV ($B) | E46: 今天公允 ($B) | F46: 加权贡献 ($B)
B47: Bear | C47: ='1_输入与假设'!C49 -> 0.25 | D47: =E16 -> 4101.9275 | E47: =F16 -> 2801.6717 | F47: =C47*E47 -> 700.41793
B48: Base | C48: ='1_输入与假设'!D49 -> 0.45 | D48: =E29 -> 5306.2726 | E48: =F29 -> 3624.2556 | F48: =C48*E48 -> 1630.915
B49: Bull | C49: ='1_输入与假设'!E49 -> 0.3 | D49: =E42 -> 7189.6471 | E49: =F42 -> 4910.6257 | F49: =C49*E49 -> 1473.1877
...

Sheet 4_价位分析
B2: 价位分析与决策框架
B3: 在不同买入价位下的预期回报 — 帮助判断当前是否为好买点
B5: 一、关键引用值
B7: 当前股价 ($) | C7: ='1_输入与假设'!C7 -> 395
B8: 当前市值 ($B) | C8: ='1_输入与假设'!C9 -> 4785.82
B9: Bear 公允价值 ($B) | C9: ='3_SOTP估值'!F16 -> 2801.6717
B10: Base 公允价值 ($B) | C10: ='3_SOTP估值'!F29 -> 3624.2556
B11: Bull 公允价值 ($B) | C11: ='3_SOTP估值'!F42 -> 4910.6257
B12: 加权公允价值 ($B) | C12: ='3_SOTP估值'!F50 -> 3804.5206
B13: 折现率 | C13: ='1_输入与假设'!C10 -> 0.1
B15: 二、不同买入价的 4 年（到 2030）期望回报
B16: 注：年化 = (2030 EV+期权)/今天买入市值)^(1/4) − 1，即从今天到 2030 的 CAGR；公允买入对应折现率 10%
B17: 买入价 ($B) | C17: vs 当前 (%) | D17: Bear 年化 | E17: Base 年化 | F17: Bull 年化 | G17: 加权年化 | H17: 解读
B18: =$C$8*0.7 -> 3350.074 | C18: -0.3 | D18: =(('3_SOTP估值'!$E$16+'6_期权价值'!$F$20*(1+'1_输入与假设'!$C$10)^4)/B18)^(1/4)-1 -> 0.054523074 | E18: =(('3_SOTP估值'!$E$29+'6_期权价值'!$F$20*(1+'1_输入与假设'!$C$10)^4)/B18)^(1/4)-1 -> 0.12399387 | F18: =(('3_SOTP估值'!$E$42+'6_期权价值'!$F$20*(1+'1_输入与假设'!$C$10)^4)/B18)^(1/4)-1 -> 0.21206692 | G18: =D18*'1_输入与假设'!$C$49+E18*'1_输入与假设'!$D$49+F18*'1_输入与假设'!$E$49 -> 0.13304808 | H18: -30% 大幅下跌
B19: =$C$8*0.85 -> 4067.947 | C19: -0.15 | D19: =(('3_SOTP估值'!$E$16+'6_期权价值'!$F$20*(1+'1_输入与假设'!$C$10)^4)/B19)^(1/4)-1 -> 0.0045599636 | E19: =(('3_SOTP估值'!$E$29+'6_期权价值'!$F$20*(1+'1_输入与假设'!$C$10)^4)/B19)^(1/4)-1 -> 0.070739245 | F19: =(('3_SOTP估值'!$E$42+'6_期权价值'!$F$20*(1+'1_输入与假设'!$C$10)^4)/B19)^(1/4)-1 -> 0.15463941 | G19: =D19*'1_输入与假设'!$C$49+E19*'1_输入与假设'!$D$49+F19*'1_输入与假设'!$E$49 -> 0.079364473 | H19: -15% 中度下跌
B20: =$C$8*1 -> 4785.82 | C20: 0 | D20: =(('3_SOTP估值'!$E$16+'6_期权价值'!$F$20*(1+'1_输入与假设'!$C$10)^4)/B20)^(1/4)-1 -> -0.035437004 | E20: =(('3_SOTP估值'!$E$29+'6_期权价值'!$F$20*(1+'1_输入与假设'!$C$10)^4)/B20)^(1/4)-1 -> 0.028107323 | F20: =(('3_SOTP估值'!$E$42+'6_期权价值'!$F$20*(1+'1_输入与假设'!$C$10)^4)/B20)^(1/4)-1 -> 0.10866696 | G20: =D20*'1_输入与假设'!$C$49+E20*'1_输入与假设'!$D$49+F20*'1_输入与假设'!$E$49 -> 0.036389134 | H20: 当前价
B21: =$C$8*1.15 -> 5503.693 | C21: 0.15 | D21: =(('3_SOTP估值'!$E$16+'6_期权价值'!$F$20*(1+'1_输入与假设'!$C$10)^4)/B21)^(1/4)-1 -> -0.068557314 | E21: =(('3_SOTP估值'!$E$29+'6_期权价值'!$F$20*(1+'1_输入与假设'!$C$10)^4)/B21)^(1/4)-1 -> -0.0071949162 | F21: =(('3_SOTP估值'!$E$42+'6_期权价值'!$F$20*(1+'1_输入与假设'!$C$10)^4)/B21)^(1/4)-1 -> 0.07059854 | G21: =D21*'1_输入与假设'!$C$49+E21*'1_输入与假设'!$D$49+F21*'1_输入与假设'!$E$49 -> 0.00080252119 | H21: +15% 上涨
B22: =$C$8*1.3 -> 6221.566 | C22: 0.3 | D22: =(('3_SOTP估值'!$E$16+'6_期权价值'!$F$20*(1+'1_输入与假设'!$C$10)^4)/B22)^(1/4)-1 -> -0.096673483 | E22: =(('3_SOTP估值'!$E$29+'6_期权价值'!$F$20*(1+'1_输入与假设'!$C$10)^4)/B22)^(1/4)-1 -> -0.037163347 | F22: =(('3_SOTP估值'!$E$42+'6_期权价值'!$F$20*(1+'1_输入与假设'!$C$10)^4)/B22)^(1/4)-1 -> 0.038281866 | G22: =D22*'1_输入与假设'!$C$49+E22*'1_输入与假设'!$D$49+F22*'1_输入与假设'!$E$49 -> -0.029407317 | H22: +30% 大涨
B23: =$C$8*1.5 -> 7178.73 | C23: 0.5 | D23: =(('3_SOTP估值'!$E$16+'6_期权价值'!$F$20*(1+'1_输入与假设'!$C$10)^4)/B23)^(1/4)-1 -> -0.12841894 | E23: =(('3_SOTP估值'!$E$29+'6_期权价值'!$F$20*(1+'1_输入与假设'!$C$10)^4)/B23)^(1/4)-1 -> -0.071000163 | F23: =(('3_SOTP估值'!$E$42+'6_期权价值'!$F$20*(1+'1_输入与假设'!$C$10)^4)/B23)^(1/4)-1 -> 0.0017936904 | G23: =D23*'1_输入与假设'!$C$49+E23*'1_输入与假设'!$D$49+F23*'1_输入与假设'!$E$49 -> -0.063516702 | H23: +50% 大涨
B26: 三、决策框架
B28: 当前价位定位
B29: 当前市值 | C29: =$C$8 -> 4785.82
B30: 隐含情景 | C30: =IF(ABS(C8-C9)<ABS(C8-C10),"接近 Bear",IF(ABS(C8-C10)<ABS(C8-C11),"接近 Base","接近 Bull")) -> 接近 Bull
B31: 当前价 vs Bear 公允 | C31: =C8/C9-1 -> 0.70820157
B32: 当前价 vs Base 公允 | C32: =C8/C10-1 -> 0.32049739
B33: 当前价 vs Bull 公允 | C33: =C8/C11-1 -> -0.025415446
B34: 当前价 vs 加权公允 | C34: =C8/C12-1 -> 0.25792983
B36: 决策矩阵
B37: 当前价 vs 加权公允 | C37: 决策建议 | D37: 理由
B38: < -20% | C38: ⭐ 买入信号 | D38: 估值显著低估; 加权年化回报 > 折现率
B39: -20% 至 -5% | C39: ✅ 合理买点 | D39: 小幅低估; 期望回报接近或略高于折现率
B40: -5% 至 +5% | C40: ➖ 中性持有 | D40: 基本 fair; 期望回报 ≈ 折现率 (10%)
B41: +5% 至 +20% | C41: ⚠️ 警惕 | D41: 已部分透支 Bull case; 期望回报压缩
B42: > +20% | C42: ❌ 避免买入 | D42: 估值显著透支; 期望回报远低于折现率
B44: ⭐ 基于当前数据的决策
B46: =IF(C34<-0.2,"⭐ 买入信号 - 估值显著低估",IF(C34<-0.05,"✅ 合理买点 - 小幅低估",IF(C34<0.05,"➖ 中性持有 - 基本 fair",IF(C34<0.2,"⚠️ 警惕 - 部分透支 Bull","❌ 避免买入 - 估值显著透支")))) -> ❌ 避免买入 - 估值显著透支
B50: 四、单股视角（含回购建模）
B52: Bear 今天单股公允 ($) | C52: ='3_SOTP估值'!F64 -> 258.35589
B53: Base 今天单股公允 ($) | C53: ='3_SOTP估值'!F65 -> 333.46464
B54: Bull 今天单股公允 ($) | C54: ='3_SOTP估值'!F66 -> 450.92094
...

Sheet 5_季度跟踪
B2: 季度跟踪 · 实际 vs 预测
B3: 每季度财报后填入实际营收, 验证假设是否仍 valid
B5: 财报季度 | C5: 日期 | D5: Search | E5: YouTube | F5: Cloud | G5: Workspace | H5: Pixel/Android | I5: Other Bets | J5: 总营收 | K5: 备注
B6: Q1 2026
B7: Q2 2026
B8: Q3 2026
B9: Q4 2026
B10: Q1 2027
B11: Q2 2027
B12: Q3 2027
B13: Q4 2027
B14: Q1 2028
B15: Q2 2028
B16: Q3 2028
B17: Q4 2028
B20: 关键事件日志
B22: 日期 | C22: 事件类型 | D22: 描述 | E22: 影响（业务） | F22: 需要调整假设？
B35: 每季度财报后的检查清单
B36: □ 1. 在 Sheet 5 上方表格填入新季度营收
B37: □ 2. 计算 TTM (滚动 4 季度) 营收
B38: □ 3. 与 Sheet 1 的 2025 基线对比 — 如果偏离 > 5%, 更新 Sheet 1
B39: □ 4. 如果重大事件 (DOJ 裁决、大额收购、Capex 削减), 在事件日志记录
B40: □ 5. 如果增长率显著偏离假设, 调整 Sheet 1 的 CAGR
B41: □ 6. 如果反垄断风险加剧, 调整 Sheet 1 的 Bear/Base 倍数（向下）
B42: □ 7. 检查 Sheet 4 的"决策建议"是否变化
B43: □ 8. 如果决策从"中性"变成"买入信号"或"避免", 写一份分析说明
B44: □ 9. 把更新结果加进 V5C 项目 reflections/06 笔记
B45: □ 10. 不基于单季度数据修改 V5C 3.3a (24 个月承诺)

Sheet 6_期权价值
B2: 期权组合估值（Real Option Value）
B3: 原理：每个 R&D 期权 = 上限估值 × 概率 × 时间折现 (4 年)；不重复计入主 SOTP
B5: 一、期权识别与估值
B7: 期权 | C7: 当前估值锚 ($B) | D7: 上限估值 ($B) | E7: 5年成熟概率 | F7: 今天期望值 ($B) | G7: 依据 / 备注
B8: Isomorphic Labs | C8: 2.5 | D8: 100 | E8: 0.1 | F8: =MAX(C8, D8*E8) -> 10 | G8: 2025/3 Series A $600M, $2.5B 估值；Eli Lilly+Novartis 合作 $3B 里程碑；Hassabis 目标 $100B AI 药物业务
B9: Waymo（已运营+扩张溢价） | C9: 40 | D9: 200 | E9: 0.2 | F9: =MAX(C9, D9*E9) -> 40 | G9: 当前 $40B+ 二级市场估值；2025 起全美扩张；20% 概率成长为 $200B（自动驾驶规模化）
B10: GameNGen / Genie 3 | C10: 0 | D10: 100 | E10: 0.05 | F10: =MAX(C10, D10*E10) -> 5 | G10: Pre-revenue；与 Sora 同档；5% 概率颠覆游戏/视频内容
B11: Project Astra（通用 AI 助手） | C11: 0 | D11: 80 | E11: 0.05 | F11: =MAX(C11, D11*E11) -> 4 | G11: Pre-revenue；整合 Pixel/Android 生态；5% 概率取代 Gemini App 成为入口
B12: AlphaProteo / Robotics / 其他 | C12: 0 | D12: 50 | E12: 0.1 | F12: =MAX(C12, D12*E12) -> 5 | G12: 组合期权：蛋白设计 + 机器人 + 量子计算等
B13: 期权组合期望值合计 | F13: =SUM(F8:F12) -> 64
B15: 二、保守调整与时间折现
B17: 保守系数（避免乐观偏差） | C17: 0.7 | D17: 默认 70%；DeepMind R&D 历史 hit rate
B18: 5 年时间折现因子（@10%） | C18: =1/(1+0.1)^5 -> 0.62092132 | D18: 从 2031 视角折回今天
B19: 调整后期望值 | F19: =F13*C17*C18 -> 27.817275
B20: ⭐ 计入 SOTP 的期权价值 | F20: =F19 -> 27.817275
B22: 三、为什么这样建模
B23: · 主 SOTP（Sheet 3）只算"已有营收 × 多倍 × 预测增速"，会系统性低估 R&D 期权
B24: · DeepMind / Isomorphic / Waymo 等 pre-revenue 业务用传统 P/S 倍数 = 0，但实际有 option value
B25: · 概率 × 上限估值 比"假设它会成为 $X 业务"更稳健（Real Options 理论）
B26: · 保守系数 0.7 进一步惩罚乐观偏差
B27: · 时间折现 0.621 反映"5 年才能成熟"的耐心溢价
B29: 注：Waymo 当前 $40B 已是市场锚点（不只是期权），上限 $200B 反映"全美 50 城自动驾驶规模化"的乐观情景

Sheet 7_AI_KPI跟踪
B2: AI 业务 KPI 季度跟踪表
B3: 每季度 GOOG 财报后更新；用于校准 Sheet 1 的 CAGR 假设
B5: 一、Cloud AI KPI
B7: KPI | C7: Q1 2026 | D7: Q2 2026 | E7: Q3 2026 | F7: Q4 2026 | G7: 警戒阈值 | H7: 说明
B8: Cloud 季度营收 ($B) | C8: 20.0 | G8: < 22 警戒 | H8: Q1 2026 已 $20B
B9: Cloud YoY 增速 | C9: 63% | G9: < 50% 警戒 | H9: 加速期；< 50% 表示见顶
B10: Cloud RPO ($B) | C10: 462 | G10: 环比 -10% 警戒 | H10: Q4 25: $240B → Q1 26: $462B
B11: Cloud GenAI 产品 YoY | C11: +800% | G11: < 200% 警戒 | H11: +800% 是历史峰值
B12: Cloud 营业利润率 | C12: ~14% | G12: < 10% 警戒 | H12: 应该向 AWS 30%+ 收敛
B14: 二、Search AI KPI
B16: KPI | C16: Q1 2026 | D16: Q2 2026 | E16: Q3 2026 | F16: Q4 2026 | G16: 警戒阈值 | H16: 说明
B17: Search & Other 季度营收 ($B) | C17: 60.4 | G17: < 60 警戒 | H17: Q1 2026 +19% YoY
B18: Search YoY 增速 | C18: +19% | G18: < 12% 警戒 | H18: 当前在加速期
B19: AI Overviews 月活 (B) | C19: 2.0 | G19: 环比 +0.1 健康 | H19: 200+ 国家覆盖
B20: AI Mode DAU (M) | C20: 75 | G20: 环比 +5 健康 | H20: US/India
B21: AI Overview SERP 含广告占比 | C21: 25.5% | G21: 环比 +1pp 健康 | H21: 从 1月 3% 升
B22: 反垄断进展 | C22: 上诉中 | G22: 强制分拆 = 重击 | H22: 2026/02 DOJ 上诉
B24: 三、Workspace AI KPI
B26: KPI | C26: Q1 2026 | D26: Q2 2026 | E26: Q3 2026 | F26: Q4 2026 | G26: 警戒阈值 | H26: 说明
B27: 付费业务用户 (M) | C27: 100+ | G27: <95 警戒 | H27: 含 Gemini AI 内置
B28: 订阅总数 (M, 含 YT) | C28: 325 | G28: 环比 +5 健康 | H28: Q4 25 数据
B29: Gemini App 月活 (M) | C29: ~400 | G29: <350 警戒 | H29: 消费端独立 App
B30: Workspace AI ARPU 隐含 ($/月) | C30: ~12 | G30: < 10 警戒 | H30: 内置 AI 价值
B33: 四、期权业务里程碑
B35: 业务 | C35: 关键里程碑 | D35: 当前状态 | E35: 预期时间 | F35: 影响
B36: Isomorphic Labs | C36: 首个 AI 设计药物入临床 | D36: pre-clinical | E36: 2026 Q4 | F36: 若成功，估值翻 3-5x
B37: Waymo | C37: 全美扩张到 20+ 城 | D37: 5 城运营 | E37: 2027 | F37: 估值锚从 $40B 升至 $80B+
B38: Gemini 4 | C38: 推理 + agentic 能力追赶 GPT-5 | D38: 研发中 | E38: 2026 H2 | F38: 如果落后，Cloud AI 倍数压缩
B39: Project Astra | C39: 消费版正式上线 | D39: 内测 | E39: 2026 H2 | F39: 可能取代 Gemini App
B40: TPU v8 | C40: 量产，进一步提升训练效率 | D40: 设计完成 | E40: 2027 | F40: 强化 Cloud 成本优势
B43: 五、使用方法
B44: 1. 每季度 GOOG 财报当天填入 C-F 列对应季度数据
B45: 2. 若 KPI 触及警戒阈值，反向调整 Sheet 1 对应业务的 CAGR 假设
B46: 3. 重大里程碑达成（成功/失败），调整 Sheet 6 期权概率
B47: 4. 不要每周更新 — 季度颗粒度足够，避免 noise
