Workbook

Sheet 1_输入与假设
B2: Tesla (TSLA) 估值锚定模型 v1.0
B3: 方法：SOTP 双层（主营 EV/Sales + 期权 Real Option）— 沉淀期内的认知建设
B5: 一、当前市场数据
B7: 当前股价 ($) | C7: 428 | D7: 2026/05/10 实时
B8: 流通股本 (Diluted, B) | C8: 3.538 | D8: 10-Q Q1 2026 cover
B9: 当前市值 ($B) | C9: =C7*C8 -> 1514.264 | D9: 自动 = C7 × C8
B10: 折现率 (WACC) | C10: 0.1 | D10: 默认 10%
B11: 股本年增率 (SBC 稀释 - 回购) | C11: 0.005 | D11: 净稀释 ~0.5%/年（SBC vs 暂无回购）
B12: FSD 订阅活跃数 (M) | C12: 1.28 | D12: Q1 2026: 1.28M, YoY +51%
B13: FSD 月费 ($) | C13: 99 | D13: 订阅价
B16: 二、TTM 营收基线（基于 2025-Q1 → 2026-Q1 财报）
B18: 业务线 | C18: TTM 营收 ($B) | D18: 说明 | G18: 数据来源
B19: Auto Sales (传统车型) | C19: 70.37 | D19: 含 Model 3/Y/S/X/Cybertruck | G19: Q1 2026 Update PDF
B20: Auto Regulatory Credits | C20: 1.78 | D20: 监管 credits, 高利润但萎缩中 | G20: Q1 2026 Update PDF
B21: Auto Leasing | C21: 1.65 | D21: 租赁业务, 稳定缓退 | G21: Q1 2026 Update PDF
B22: Energy (发电+储能) | C22: 12.45 | D22: Megapack/Powerwall, 大客户驱动 | G22: Q1 2026 Update PDF
B23: Services & Other | C23: 13.64 | D23: 含 Supercharging/FSD 订阅/Insurance/Parts | G23: Q1 2026 Update PDF
B24: 合计 TTM | C24: 99.89 | D24: vs 财报 TTM $97.88B
B27: 三、三情景 CAGR 假设（基本面维度，5 年 2026 → 2031）
B29: 业务线 | C29: Bear CAGR | D29: Base CAGR | E29: Bull CAGR | F29: 说明 / 驱动逻辑
B30: Auto Sales | C30: 0.03 | D30: 0.1 | E30: 0.2 | F30: Bull: 经济车型 + Cybercab 量产；Base: 平稳扩张；Bear: 价格战压力
B31: Auto Regulatory Credits | C31: -0.3 | D31: -0.15 | E31: -0.05 | F31: 联邦补贴退坡，2030 前可能接近 0
B32: Auto Leasing | C32: -0.1 | D32: 0 | E32: 0.05 | F32: 客户偏好购买而非租赁
B33: Energy | C33: 0.15 | D33: 0.3 | E33: 0.5 | F33: Bull: AI 数据中心爆发需求；Base: Megapack 3 + 全球电网；Bear: 竞争加剧
B34: Services & Other | C34: 0.2 | D34: 0.35 | E34: 0.55 | F34: Bull: FSD 订阅 + Insurance + Supercharging 三引擎；Base: FSD 渗透提升
B37: 四、基准倍数（EV/Sales，跨情景固定 — 市场情绪独立维度）
B39: 业务线 | C39: 基准 P/Sales | D39: 历史区间 | E39: 可比公司参考
B40: Auto Sales | C40: 2.5 | D40: 0.5-3x 汽车业 | E40: TM 0.6x, F 0.3x, BYD 1.2x;Tesla 溢价反映成长
B41: Auto Regulatory Credits | C41: 5 | D41: 高毛利但消亡 | E41: 即将归零的资产
B42: Auto Leasing | C42: 1.5 | D42: 汽车金融 | E42: GM Financial 类
B43: Energy | C43: 8 | D43: 6-12x 高增长 | E43: NEE 4x, ENPH 8x, SEDG 5x
B44: Services & Other | C44: 12 | D44: 8-18x SaaS+ | E44: MSFT 13x, ADBE 10x（含 FSD 订阅）
B47: 五、情景概率分配
C48: Bear | D48: Base | E48: Bull | F48: 合计
B49: 概率 | C49: 0.25 | D49: 0.45 | E49: 0.3 | F49: =SUM(C49:E49) -> 1
B52: 六、使用提示
B53: 1. 每月更新 C7（股价）
B54: 2. 季报后更新 C12（FSD 订阅数）
B55: 3. 财报后更新 C19-C23（5 业务线营收）
B56: 4. 期权价值在 Sheet 6 单独管理
...

Sheet 2_5年预测
B2: Tesla 5 年三情景营收预测 (TTM Q1 2026 → 2031)
B3: 基于 Sheet 1 输入自动计算 — 你不需要修改这里
B5: Bear 情景
B7: 业务线 | C7: 2026 TTM | D7: 2027 | E7: 2028 | F7: 2029 | G7: 2030 | H7: 2031
B8: ='1_输入与假设'!B19 -> Auto Sales (传统车型) | C8: ='1_输入与假设'!C19 -> 70.37 | D8: =C8*(1+'1_输入与假设'!C30)^1 -> 72.4811 | E8: =C8*(1+'1_输入与假设'!C30)^2 -> 74.655533 | F8: =C8*(1+'1_输入与假设'!C30)^3 -> 76.895199 | G8: =C8*(1+'1_输入与假设'!C30)^4 -> 79.202055 | H8: =C8*(1+'1_输入与假设'!C30)^5 -> 81.578117
B9: ='1_输入与假设'!B20 -> Auto Regulatory Credits | C9: ='1_输入与假设'!C20 -> 1.78 | D9: =C9*(1+'1_输入与假设'!C31)^1 -> 1.246 | E9: =C9*(1+'1_输入与假设'!C31)^2 -> 0.8722 | F9: =C9*(1+'1_输入与假设'!C31)^3 -> 0.61054 | G9: =C9*(1+'1_输入与假设'!C31)^4 -> 0.427378 | H9: =C9*(1+'1_输入与假设'!C31)^5 -> 0.2991646
B10: ='1_输入与假设'!B21 -> Auto Leasing | C10: ='1_输入与假设'!C21 -> 1.65 | D10: =C10*(1+'1_输入与假设'!C32)^1 -> 1.485 | E10: =C10*(1+'1_输入与假设'!C32)^2 -> 1.3365 | F10: =C10*(1+'1_输入与假设'!C32)^3 -> 1.20285 | G10: =C10*(1+'1_输入与假设'!C32)^4 -> 1.082565 | H10: =C10*(1+'1_输入与假设'!C32)^5 -> 0.9743085
B11: ='1_输入与假设'!B22 -> Energy (发电+储能) | C11: ='1_输入与假设'!C22 -> 12.45 | D11: =C11*(1+'1_输入与假设'!C33)^1 -> 14.3175 | E11: =C11*(1+'1_输入与假设'!C33)^2 -> 16.465125 | F11: =C11*(1+'1_输入与假设'!C33)^3 -> 18.934894 | G11: =C11*(1+'1_输入与假设'!C33)^4 -> 21.775128 | H11: =C11*(1+'1_输入与假设'!C33)^5 -> 25.041397
B12: ='1_输入与假设'!B23 -> Services & Other | C12: ='1_输入与假设'!C23 -> 13.64 | D12: =C12*(1+'1_输入与假设'!C34)^1 -> 16.368 | E12: =C12*(1+'1_输入与假设'!C34)^2 -> 19.6416 | F12: =C12*(1+'1_输入与假设'!C34)^3 -> 23.56992 | G12: =C12*(1+'1_输入与假设'!C34)^4 -> 28.283904 | H12: =C12*(1+'1_输入与假设'!C34)^5 -> 33.940685
B13: Bear 总营收 | C13: =SUM(C8:C12) -> 99.89 | D13: =SUM(D8:D12) -> 105.8976 | E13: =SUM(E8:E12) -> 112.97096 | F13: =SUM(F8:F12) -> 121.2134 | G13: =SUM(G8:G12) -> 130.77103 | H13: =SUM(H8:H12) -> 141.83367
B15: Base 情景
B17: 业务线 | C17: 2026 TTM | D17: 2027 | E17: 2028 | F17: 2029 | G17: 2030 | H17: 2031
B18: ='1_输入与假设'!B19 -> Auto Sales (传统车型) | C18: ='1_输入与假设'!C19 -> 70.37 | D18: =C18*(1+'1_输入与假设'!D30)^1 -> 77.407 | E18: =C18*(1+'1_输入与假设'!D30)^2 -> 85.1477 | F18: =C18*(1+'1_输入与假设'!D30)^3 -> 93.66247 | G18: =C18*(1+'1_输入与假设'!D30)^4 -> 103.02872 | H18: =C18*(1+'1_输入与假设'!D30)^5 -> 113.33159
B19: ='1_输入与假设'!B20 -> Auto Regulatory Credits | C19: ='1_输入与假设'!C20 -> 1.78 | D19: =C19*(1+'1_输入与假设'!D31)^1 -> 1.513 | E19: =C19*(1+'1_输入与假设'!D31)^2 -> 1.28605 | F19: =C19*(1+'1_输入与假设'!D31)^3 -> 1.0931425 | G19: =C19*(1+'1_输入与假设'!D31)^4 -> 0.92917112 | H19: =C19*(1+'1_输入与假设'!D31)^5 -> 0.78979546
B20: ='1_输入与假设'!B21 -> Auto Leasing | C20: ='1_输入与假设'!C21 -> 1.65 | D20: =C20*(1+'1_输入与假设'!D32)^1 -> 1.65 | E20: =C20*(1+'1_输入与假设'!D32)^2 -> 1.65 | F20: =C20*(1+'1_输入与假设'!D32)^3 -> 1.65 | G20: =C20*(1+'1_输入与假设'!D32)^4 -> 1.65 | H20: =C20*(1+'1_输入与假设'!D32)^5 -> 1.65
B21: ='1_输入与假设'!B22 -> Energy (发电+储能) | C21: ='1_输入与假设'!C22 -> 12.45 | D21: =C21*(1+'1_输入与假设'!D33)^1 -> 16.185 | E21: =C21*(1+'1_输入与假设'!D33)^2 -> 21.0405 | F21: =C21*(1+'1_输入与假设'!D33)^3 -> 27.35265 | G21: =C21*(1+'1_输入与假设'!D33)^4 -> 35.558445 | H21: =C21*(1+'1_输入与假设'!D33)^5 -> 46.225978
B22: ='1_输入与假设'!B23 -> Services & Other | C22: ='1_输入与假设'!C23 -> 13.64 | D22: =C22*(1+'1_输入与假设'!D34)^1 -> 18.414 | E22: =C22*(1+'1_输入与假设'!D34)^2 -> 24.8589 | F22: =C22*(1+'1_输入与假设'!D34)^3 -> 33.559515 | G22: =C22*(1+'1_输入与假设'!D34)^4 -> 45.305345 | H22: =C22*(1+'1_输入与假设'!D34)^5 -> 61.162216
B23: Base 总营收 | C23: =SUM(C18:C22) -> 99.89 | D23: =SUM(D18:D22) -> 115.169 | E23: =SUM(E18:E22) -> 133.98315 | F23: =SUM(F18:F22) -> 157.31778 | G23: =SUM(G18:G22) -> 186.47168 | H23: =SUM(H18:H22) -> 223.15958
B25: Bull 情景
B27: 业务线 | C27: 2026 TTM | D27: 2027 | E27: 2028 | F27: 2029 | G27: 2030 | H27: 2031
B28: ='1_输入与假设'!B19 -> Auto Sales (传统车型) | C28: ='1_输入与假设'!C19 -> 70.37 | D28: =C28*(1+'1_输入与假设'!E30)^1 -> 84.444 | E28: =C28*(1+'1_输入与假设'!E30)^2 -> 101.3328 | F28: =C28*(1+'1_输入与假设'!E30)^3 -> 121.59936 | G28: =C28*(1+'1_输入与假设'!E30)^4 -> 145.91923 | H28: =C28*(1+'1_输入与假设'!E30)^5 -> 175.10308
B29: ='1_输入与假设'!B20 -> Auto Regulatory Credits | C29: ='1_输入与假设'!C20 -> 1.78 | D29: =C29*(1+'1_输入与假设'!E31)^1 -> 1.691 | E29: =C29*(1+'1_输入与假设'!E31)^2 -> 1.60645 | F29: =C29*(1+'1_输入与假设'!E31)^3 -> 1.5261275 | G29: =C29*(1+'1_输入与假设'!E31)^4 -> 1.4498211 | H29: =C29*(1+'1_输入与假设'!E31)^5 -> 1.3773301
B30: ='1_输入与假设'!B21 -> Auto Leasing | C30: ='1_输入与假设'!C21 -> 1.65 | D30: =C30*(1+'1_输入与假设'!E32)^1 -> 1.7325 | E30: =C30*(1+'1_输入与假设'!E32)^2 -> 1.819125 | F30: =C30*(1+'1_输入与假设'!E32)^3 -> 1.9100812 | G30: =C30*(1+'1_输入与假设'!E32)^4 -> 2.0055853 | H30: =C30*(1+'1_输入与假设'!E32)^5 -> 2.1058646
B31: ='1_输入与假设'!B22 -> Energy (发电+储能) | C31: ='1_输入与假设'!C22 -> 12.45 | D31: =C31*(1+'1_输入与假设'!E33)^1 -> 18.675 | E31: =C31*(1+'1_输入与假设'!E33)^2 -> 28.0125 | F31: =C31*(1+'1_输入与假设'!E33)^3 -> 42.01875 | G31: =C31*(1+'1_输入与假设'!E33)^4 -> 63.028125 | H31: =C31*(1+'1_输入与假设'!E33)^5 -> 94.542187
B32: ='1_输入与假设'!B23 -> Services & Other | C32: ='1_输入与假设'!C23 -> 13.64 | D32: =C32*(1+'1_输入与假设'!E34)^1 -> 21.142 | E32: =C32*(1+'1_输入与假设'!E34)^2 -> 32.7701 | F32: =C32*(1+'1_输入与假设'!E34)^3 -> 50.793655 | G32: =C32*(1+'1_输入与假设'!E34)^4 -> 78.730165 | H32: =C32*(1+'1_输入与假设'!E34)^5 -> 122.03176
B33: Bull 总营收 | C33: =SUM(C28:C32) -> 99.89 | D33: =SUM(D28:D32) -> 127.6845 | E33: =SUM(E28:E32) -> 165.54098 | F33: =SUM(F28:F32) -> 217.84797 | G33: =SUM(G28:G32) -> 291.13293 | H33: =SUM(H28:H32) -> 395.16022

Sheet 3_SOTP估值
B2: Tesla SOTP 估值（v1.0：主营 + 期权双层）
B3: 主营业务 EV/Sales 估值 + 期权组合 Real Option Value
B5: Bear 情景 SOTP
B7: 业务线 | C7: 2031 营收 | D7: 倍数 | E7: 2031 EV | F7: 折现回 2026
B8: ='1_输入与假设'!B19 -> Auto Sales (传统车型) | C8: ='2_5年预测'!H8 -> 81.578117 | D8: ='1_输入与假设'!C40 -> 2.5 | E8: =C8*D8 -> 203.94529 | F8: =E8/(1+'1_输入与假设'!C10)^5 -> 126.63398
B9: ='1_输入与假设'!B20 -> Auto Regulatory Credits | C9: ='2_5年预测'!H9 -> 0.2991646 | D9: ='1_输入与假设'!C41 -> 5 | E9: =C9*D9 -> 1.495823 | F9: =E9/(1+'1_输入与假设'!C10)^5 -> 0.9287884
B10: ='1_输入与假设'!B21 -> Auto Leasing | C10: ='2_5年预测'!H10 -> 0.9743085 | D10: ='1_输入与假设'!C42 -> 1.5 | E10: =C10*D10 -> 1.4614627 | F10: =E10/(1+'1_输入与假设'!C10)^5 -> 0.90745338
B11: ='1_输入与假设'!B22 -> Energy (发电+储能) | C11: ='2_5年预测'!H11 -> 25.041397 | D11: ='1_输入与假设'!C43 -> 8 | E11: =C11*D11 -> 200.33118 | F11: =E11/(1+'1_输入与假设'!C10)^5 -> 124.3899
B12: ='1_输入与假设'!B23 -> Services & Other | C12: ='2_5年预测'!H12 -> 33.940685 | D12: ='1_输入与假设'!C44 -> 12 | E12: =C12*D12 -> 407.28822 | F12: =E12/(1+'1_输入与假设'!C10)^5 -> 252.89394
B13: Bear 加和（主营业务） | E13: =SUM(E8:E12) -> 814.52197 | F13: =SUM(F8:F12) -> 505.75406
B15: Base 情景 SOTP
B17: 业务线 | C17: 2031 营收 | D17: 倍数 | E17: 2031 EV | F17: 折现回 2026
B18: ='1_输入与假设'!B19 -> Auto Sales (传统车型) | C18: ='2_5年预测'!H18 -> 113.33159 | D18: ='1_输入与假设'!C40 -> 2.5 | E18: =C18*D18 -> 283.32897 | F18: =E18/(1+'1_输入与假设'!C10)^5 -> 175.925
B19: ='1_输入与假设'!B20 -> Auto Regulatory Credits | C19: ='2_5年预测'!H19 -> 0.78979546 | D19: ='1_输入与假设'!C41 -> 5 | E19: =C19*D19 -> 3.9489773 | F19: =E19/(1+'1_输入与假设'!C10)^5 -> 2.4520042
B20: ='1_输入与假设'!B21 -> Auto Leasing | C20: ='2_5年预测'!H20 -> 1.65 | D20: ='1_输入与假设'!C42 -> 1.5 | E20: =C20*D20 -> 2.475 | F20: =E20/(1+'1_输入与假设'!C10)^5 -> 1.5367803
B21: ='1_输入与假设'!B22 -> Energy (发电+储能) | C21: ='2_5年预测'!H21 -> 46.225978 | D21: ='1_输入与假设'!C43 -> 8 | E21: =C21*D21 -> 369.80783 | F21: =E21/(1+'1_输入与假设'!C10)^5 -> 229.62157
B22: ='1_输入与假设'!B23 -> Services & Other | C22: ='2_5年预测'!H22 -> 61.162216 | D22: ='1_输入与假设'!C44 -> 12 | E22: =C22*D22 -> 733.94659 | F22: =E22/(1+'1_输入与假设'!C10)^5 -> 455.72309
B23: Base 加和（主营业务） | E23: =SUM(E18:E22) -> 1393.5074 | F23: =SUM(F18:F22) -> 865.25844
B25: Bull 情景 SOTP
B27: 业务线 | C27: 2031 营收 | D27: 倍数 | E27: 2031 EV | F27: 折现回 2026
B28: ='1_输入与假设'!B19 -> Auto Sales (传统车型) | C28: ='2_5年预测'!H28 -> 175.10308 | D28: ='1_输入与假设'!C40 -> 2.5 | E28: =C28*D28 -> 437.7577 | F28: =E28/(1+'1_输入与假设'!C10)^5 -> 271.81309
B29: ='1_输入与假设'!B20 -> Auto Regulatory Credits | C29: ='2_5年预测'!H29 -> 1.3773301 | D29: ='1_输入与假设'!C41 -> 5 | E29: =C29*D29 -> 6.8866503 | F29: =E29/(1+'1_输入与假设'!C10)^5 -> 4.276068
B30: ='1_输入与假设'!B21 -> Auto Leasing | C30: ='2_5年预测'!H30 -> 2.1058646 | D30: ='1_输入与假设'!C42 -> 1.5 | E30: =C30*D30 -> 3.1587969 | F30: =E30/(1+'1_输入与假设'!C10)^5 -> 1.9613643
B31: ='1_输入与假设'!B22 -> Energy (发电+储能) | C31: ='2_5年预测'!H31 -> 94.542187 | D31: ='1_输入与假设'!C43 -> 8 | E31: =C31*D31 -> 756.3375 | F31: =E31/(1+'1_输入与假设'!C10)^5 -> 469.62608
B32: ='1_输入与假设'!B23 -> Services & Other | C32: ='2_5年预测'!H32 -> 122.03176 | D32: ='1_输入与假设'!C44 -> 12 | E32: =C32*D32 -> 1464.3811 | F32: =E32/(1+'1_输入与假设'!C10)^5 -> 909.26543
B33: Bull 加和（主营业务） | E33: =SUM(E28:E32) -> 2668.5217 | F33: =SUM(F28:F32) -> 1656.942
B35: ⭐ 加权主营业务公允（基本面维度）
B37: 情景 | C37: 概率 | D37: 2031 EV ($B) | E37: 今天公允 ($B) | F37: 加权贡献 ($B)
B38: Bear | C38: ='1_输入与假设'!C49 -> 0.25 | D38: =E13 -> 814.52197 | E38: =F13 -> 505.75406 | F38: =C38*E38 -> 126.43851
B39: Base | C39: ='1_输入与假设'!D49 -> 0.45 | D39: =E23 -> 1393.5074 | E39: =F23 -> 865.25844 | F39: =C39*E39 -> 389.3663
B40: Bull | C40: ='1_输入与假设'!E49 -> 0.3 | D40: =E33 -> 2668.5217 | E40: =F33 -> 1656.942 | F40: =C40*E40 -> 497.08261
B41: 加权主营公允 | F41: =SUM(F38:F40) -> 1012.8874
B43: + 期权组合（Real Option Value，来自 Sheet 6） | F43: ='6_期权价值'!F22 -> 269.47985
B44: ⭐ 总公允价值（含期权） | F44: =F41+F43 -> 1282.3673
B46: 当前市值 | F46: ='1_输入与假设'!C9 -> 1514.264
B47: 当前价 vs 公允（仅主营） | F47: =F46/F41-1 -> 0.49499734
B48: 当前价 vs 总公允（含期权） | F48: =F46/F44-1 -> 0.18083487
B51: ⭐⭐ 单股估值视角（含期权 + 股本稀释）
B52: 原理：2031 股本 = 今天股本 × (1 + 稀释率)^5；单股 = 总 EV ÷ 2031 股本 ÷ 折现
B54: 情景 | C54: 2031 EV ($B) | D54: +期权 ($B) | E54: 2031 股本 (B) | F54: 今天单股公允 ($)
...

Sheet 4_价位分析
B2: Tesla 价位分析与决策框架
B3: 在不同买入价位下的预期回报 — 帮助判断当前是否为好买点
B5: 一、关键引用值
B7: 当前股价 ($) | C7: ='1_输入与假设'!C7 -> 428
B8: 当前市值 ($B) | C8: ='1_输入与假设'!C9 -> 1514.264
B9: Bear 公允价值 ($B) | C9: ='3_SOTP估值'!F13 -> 505.75406
B10: Base 公允价值 ($B) | C10: ='3_SOTP估值'!F23 -> 865.25844
B11: Bull 公允价值 ($B) | C11: ='3_SOTP估值'!F33 -> 1656.942
B12: 主营加权公允 ($B) | C12: ='3_SOTP估值'!F41 -> 1012.8874
B13: + 期权组合 ($B) | C13: ='3_SOTP估值'!F43 -> 269.47985
B14: 总公允（含期权）($B) | C14: ='3_SOTP估值'!F44 -> 1282.3673
B15: 折现率 | C15: ='1_输入与假设'!C10 -> 0.1
B17: 二、不同买入价的 5 年（到 2031）期望年化回报
B19: 买入价 ($B) | C19: vs 当前 (%) | D19: Bear 年化 | E19: Base 年化 | F19: Bull 年化 | G19: 加权年化 | H19: 解读
B20: =$C$8*0.5 -> 757.132 | C20: -0.5 | D20: =(('3_SOTP估值'!$E$13+'6_期权价值'!$F$22*(1+'1_输入与假设'!$C$10)^5)/B20)^(1/5)-1 -> 0.10521028 | E20: =(('3_SOTP估值'!$E$23+'6_期权价值'!$F$22*(1+'1_输入与假设'!$C$10)^5)/B20)^(1/5)-1 -> 0.19271727 | F20: =(('3_SOTP估值'!$E$33+'6_期权价值'!$F$22*(1+'1_输入与假设'!$C$10)^5)/B20)^(1/5)-1 -> 0.32589351 | G20: =D20*'1_输入与假设'!$C$49+E20*'1_输入与假设'!$D$49+F20*'1_输入与假设'!$E$49 -> 0.2107934 | H20: -50% 半价大跌
B21: =$C$8*0.7 -> 1059.9848 | C21: -0.3 | D21: =(('3_SOTP估值'!$E$13+'6_期权价值'!$F$22*(1+'1_输入与假设'!$C$10)^5)/B21)^(1/5)-1 -> 0.033283062 | E21: =(('3_SOTP估值'!$E$23+'6_期权价值'!$F$22*(1+'1_输入与假设'!$C$10)^5)/B21)^(1/5)-1 -> 0.11509508 | F21: =(('3_SOTP估值'!$E$33+'6_期权价值'!$F$22*(1+'1_输入与假设'!$C$10)^5)/B21)^(1/5)-1 -> 0.2396042 | G21: =D21*'1_输入与假设'!$C$49+E21*'1_输入与假设'!$D$49+F21*'1_输入与假设'!$E$49 -> 0.13199481 | H21: -30% 大幅下跌
B22: =$C$8*0.85 -> 1287.1244 | C22: -0.15 | D22: =(('3_SOTP估值'!$E$13+'6_期权价值'!$F$22*(1+'1_输入与假设'!$C$10)^5)/B22)^(1/5)-1 -> -0.0060715243 | E22: =(('3_SOTP估值'!$E$23+'6_期权价值'!$F$22*(1+'1_输入与假设'!$C$10)^5)/B22)^(1/5)-1 -> 0.072624525 | F22: =(('3_SOTP估值'!$E$33+'6_期权价值'!$F$22*(1+'1_输入与假设'!$C$10)^5)/B22)^(1/5)-1 -> 0.19239147 | G22: =D22*'1_输入与假设'!$C$49+E22*'1_输入与假设'!$D$49+F22*'1_输入与假设'!$E$49 -> 0.088880597 | H22: -15% 中度下跌
B23: =$C$8*1 -> 1514.264 | C23: 0 | D23: =(('3_SOTP估值'!$E$13+'6_期权价值'!$F$22*(1+'1_输入与假设'!$C$10)^5)/B23)^(1/5)-1 -> -0.037858565 | E23: =(('3_SOTP估值'!$E$23+'6_期权价值'!$F$22*(1+'1_输入与假设'!$C$10)^5)/B23)^(1/5)-1 -> 0.03832069 | F23: =(('3_SOTP估值'!$E$33+'6_期权价值'!$F$22*(1+'1_输入与假设'!$C$10)^5)/B23)^(1/5)-1 -> 0.15425734 | G23: =D23*'1_输入与假设'!$C$49+E23*'1_输入与假设'!$D$49+F23*'1_输入与假设'!$E$49 -> 0.054056872 | H23: 当前价
B24: =$C$8*1.15 -> 1741.4036 | C24: 0.15 | D24: =(('3_SOTP估值'!$E$13+'6_期权价值'!$F$22*(1+'1_输入与假设'!$C$10)^5)/B24)^(1/5)-1 -> -0.064380316 | E24: =(('3_SOTP估值'!$E$23+'6_期权价值'!$F$22*(1+'1_输入与假设'!$C$10)^5)/B24)^(1/5)-1 -> 0.0096990318 | F24: =(('3_SOTP估值'!$E$33+'6_期权价值'!$F$22*(1+'1_输入与假设'!$C$10)^5)/B24)^(1/5)-1 -> 0.12243985 | G24: =D24*'1_输入与假设'!$C$49+E24*'1_输入与假设'!$D$49+F24*'1_输入与假设'!$E$49 -> 0.025001441 | H24: +15% 上涨
B25: =$C$8*1.3 -> 1968.5432 | C25: 0.3 | D25: =(('3_SOTP估值'!$E$13+'6_期权价值'!$F$22*(1+'1_输入与假设'!$C$10)^5)/B25)^(1/5)-1 -> -0.087043158 | E25: =(('3_SOTP估值'!$E$23+'6_期权价值'!$F$22*(1+'1_输入与假设'!$C$10)^5)/B25)^(1/5)-1 -> -0.014758181 | F25: =(('3_SOTP估值'!$E$33+'6_期权价值'!$F$22*(1+'1_输入与假设'!$C$10)^5)/B25)^(1/5)-1 -> 0.095251801 | G25: =D25*'1_输入与假设'!$C$49+E25*'1_输入与假设'!$D$49+F25*'1_输入与假设'!$E$49 -> 0.00017356954 | H25: +30% 大涨
B26: =$C$8*1.5 -> 2271.396 | C26: 0.5 | D26: =(('3_SOTP估值'!$E$13+'6_期权价值'!$F$22*(1+'1_输入与假设'!$C$10)^5)/B26)^(1/5)-1 -> -0.11280177 | E26: =(('3_SOTP估值'!$E$23+'6_期权价值'!$F$22*(1+'1_输入与假设'!$C$10)^5)/B26)^(1/5)-1 -> -0.042556277 | F26: =(('3_SOTP估值'!$E$33+'6_期权价值'!$F$22*(1+'1_输入与假设'!$C$10)^5)/B26)^(1/5)-1 -> 0.064349829 | G26: =D26*'1_输入与假设'!$C$49+E26*'1_输入与假设'!$D$49+F26*'1_输入与假设'!$E$49 -> -0.028045819 | H26: +50% 大涨
B28: 注：年化 = ((2031 EV+期权)/今天买入市值)^(1/5) − 1；公允买入对应折现率 10%
B31: 三、决策框架
B33: 当前价位定位
B34: 当前市值 | C34: =$C$8 -> 1514.264
B35: 隐含情景 | C35: =IF(C8<C9,"低于 Bear",IF(C8<C10,"Bear-Base 区间",IF(C8<C11,"Base-Bull 区间","超 Bull"))) -> Base-Bull 区间
B36: 当前价 vs Bear 公允 | C36: =C8/C9-1 -> 1.9940719
B37: 当前价 vs Base 公允 | C37: =C8/C10-1 -> 0.75007134
B38: 当前价 vs Bull 公允 | C38: =C8/C11-1 -> -0.086109249
B39: 当前价 vs 主营加权 | C39: =C8/C12-1 -> 0.49499734
B40: 当前价 vs 总公允(含期权) | C40: =C8/C14-1 -> 0.18083487
B42: 决策矩阵（基于总公允，含期权）
B43: 偏离区间 | C43: 决策建议 | D43: 理由
B44: < -20% | C44: ⭐ 买入信号 | D44: 估值显著低估; 年化回报 > 折现率
B45: -20% 至 -5% | C45: ✅ 合理买点 | D45: 小幅低估; 期望回报接近或略高于折现率
B46: -5% 至 +5% | C46: ➖ 中性持有 | D46: 基本 fair; 期望回报 ≈ 折现率 (10%)
B47: +5% 至 +20% | C47: ⚠️ 警惕 | D47: 已部分透支 Bull case; 期望回报压缩
B48: > +20% | C48: ❌ 避免买入 | D48: 估值显著透支; 期望回报远低于折现率
B50: ⭐ 基于当前数据的决策
B51: =IF(C40<-0.2,"⭐ 买入信号 - 估值显著低估",IF(C40<-0.05,"✅ 合理买点 - 小幅低估",IF(C40<0.05,"➖ 中性持有 - 基本 fair",IF(C40<0.2,"⚠️ 警惕 - 部分透支 Bull","❌ 避免买入 - 估值显著透支")))) -> ⚠️ 警惕 - 部分透支 Bull

Sheet 5_季度跟踪
B2: Tesla 季度跟踪表 — Q1 2026 基线 + 后续填充
B5: 一、营收对比 vs 预测
B7: 业务线 | C7: Q1 2025 | D7: Q2 2025 | E7: Q3 2025 | F7: Q4 2025 | G7: Q1 2026 | H7: TTM | I7: Base 预期 Q1 | J7: 偏离
B8: Auto Sales | C8: 12.93 | D8: 15.79 | E8: 20.36 | F8: 16.75 | G8: 15.47 | H8: =D8+E8+F8+G8 -> 68.37 | I8: ='1_输入与假设'!C19/4 -> 17.5925 | J8: =G8/I8-1 -> -0.120648
B9: Auto Reg Credits | C9: 0.6 | D9: 0.44 | E9: 0.42 | F9: 0.54 | G9: 0.38 | H9: =D9+E9+F9+G9 -> 1.78 | I9: ='1_输入与假设'!C20/4 -> 0.445 | J9: =G9/I9-1 -> -0.14606742
B10: Auto Leasing | C10: 0.45 | D10: 0.44 | E10: 0.43 | F10: 0.4 | G10: 0.38 | H10: =D10+E10+F10+G10 -> 1.65 | I10: ='1_输入与假设'!C21/4 -> 0.4125 | J10: =G10/I10-1 -> -0.078787879
B11: Energy | C11: 2.73 | D11: 2.79 | E11: 3.42 | F11: 3.84 | G11: 2.41 | H11: =D11+E11+F11+G11 -> 12.46 | I11: ='1_输入与假设'!C22/4 -> 3.1125 | J11: =G11/I11-1 -> -0.22570281
B12: Services & Other | C12: 2.64 | D12: 3.05 | E12: 3.48 | F12: 3.37 | G12: 3.75 | H12: =D12+E12+F12+G12 -> 13.65 | I12: ='1_输入与假设'!C23/4 -> 3.41 | J12: =G12/I12-1 -> 0.099706745
B13: 合计 | C13: =SUM(C8:C12) -> 19.35 | D13: =SUM(D8:D12) -> 22.51 | E13: =SUM(E8:E12) -> 28.11 | F13: =SUM(F8:F12) -> 24.9 | G13: =SUM(G8:G12) -> 22.39 | H13: =SUM(H8:H12) -> 97.91 | I13: =SUM(I8:I12) -> 24.9725 | J13: =G13/I13-1 -> -0.10341376
B15: 二、季度核心指标
B17: 指标 | C17: Q1 2025 | D17: Q2 2025 | E17: Q3 2025 | F17: Q4 2025 | G17: Q1 2026 | H17: YoY
B18: 总营收 ($B) | C18: 19.34 | D18: 22.5 | E18: 28.1 | F18: 24.9 | G18: 22.39 | H18: =IF(C18=0,"n/m",G18/C18-1) -> 0.15770424
B19: 总毛利率 (%) | C19: 16.3 | D19: 17.2 | E19: 18 | F19: 20.1 | G19: 21.1 | H19: =IF(C19=0,"n/m",G19/C19-1) -> 0.29447853
B20: 营业利润率 (%) | C20: 2.1 | D20: 4.1 | E20: 5.8 | F20: 5.7 | G20: 4.2 | H20: =IF(C20=0,"n/m",G20/C20-1) -> 1
B21: Adjusted EBITDA ($B) | C21: 2.81 | D21: 3.4 | E21: 4.23 | F21: 4.15 | G21: 3.67 | H21: =IF(C21=0,"n/m",G21/C21-1) -> 0.30604982
B22: GAAP EPS ($) | C22: 0.12 | D22: 0.33 | E22: 0.39 | F22: 0.24 | G22: 0.13 | H22: =IF(C22=0,"n/m",G22/C22-1) -> 0.083333333
B23: Non-GAAP EPS ($) | C23: 0.27 | D23: 0.4 | E23: 0.5 | F23: 0.5 | G23: 0.41 | H23: =IF(C23=0,"n/m",G23/C23-1) -> 0.51851852
B24: 交付量 (千辆) | C24: 337 | D24: 384 | E24: 497 | F24: 418 | G24: 358 | H24: =IF(C24=0,"n/m",G24/C24-1) -> 0.06231454
B25: FSD 订阅 (M) | C25: 0.85 | D25: 0.95 | E25: 1.04 | F25: 1.1 | G25: 1.28 | H25: =IF(C25=0,"n/m",G25/C25-1) -> 0.50588235
B26: 储能部署 (GWh) | C26: 10.4 | D26: 9.6 | E26: 12.5 | F26: 14.2 | G26: 8.8 | H26: =IF(C26=0,"n/m",G26/C26-1) -> -0.15384615
B27: Capex ($B) | C27: 1.49 | D27: 2.39 | E27: 2.25 | F27: 2.39 | G27: 2.49 | H27: =IF(C27=0,"n/m",G27/C27-1) -> 0.67114094
B28: FCF ($B) | C28: 0.66 | D28: 0.15 | E28: 3.99 | F28: 1.42 | G28: 1.44 | H28: =IF(C28=0,"n/m",G28/C28-1) -> 1.1818182
B29: Cash + ST Investments ($B) | C29: 37 | D29: 36.8 | E29: 41.6 | F29: 44.1 | G29: 44.7 | H29: =IF(C29=0,"n/m",G29/C29-1) -> 0.20810811
B33: 使用提示
B34: · 每季报后填入新一列 (移动到右侧)
B35: · 偏离 > ±10% 警戒, 反向调整 Sheet 1 CAGR 假设
B36: · FSD 订阅是关键先行指标
B37: · 储能 -15% YoY 是当前主要警告信号, 跟踪 Q2 是否回升

Sheet 6_期权价值
B2: 特斯拉期权组合估值（Real Option Value）
B3: 原理：5 个未来业务的概率加权 + 保守系数 + 时间折现
B5: 一、五个期权业务的识别与估值
B7: 期权业务 | C7: 当前进展 | D7: 上限估值 ($B) | E7: 5年成熟概率 | F7: 今天期望值 ($B) | G7: 逻辑/参考
B8: Robotaxi 网络 | C8: Austin/Dallas/Houston 早期; Q1 累计 ~1.6M 付费英里 | D8: 500 | E8: 0.4 | F8: =D8*E8 -> 200 | G8: UBER 当前估值 $170B (1.6B 完成订单/年, 8% take rate). Tesla Robotaxi 利润率优势大 (无司机); 假设 5 年达 1/3 UBER 规模 + 4x 利润率溢价
B9: Cybercab 车型 | C9: 试点生产 (Gigafactory Texas) | D9: 200 | E9: 0.6 | F9: =D9*E9 -> 120 | G9: 设计为最便宜的自动驾驶车型, 用于 Robotaxi 车队; 假设 5 年 500K/年产能 × $25K 单价 × 8x P/S 倍数
B10: Tesla Semi | C10: 试点生产, 公共 Megacharger 部署中 | D10: 100 | E10: 0.7 | F10: =D10*E10 -> 70 | G10: 美国卡车市场 ~$200B/年; 假设 Tesla Semi 5 年占 5% 份额 × 8x P/S
B11: Optimus 机器人 | C11: 工厂建设中: 第 1 代 100 万/年 (Fremont 替换 S/X 线); 第 2 代 1000 万/年 | D11: 1000 | E11: 0.2 | F11: =D11*E11 -> 200 | G11: 马斯克目标年产 1000 万台 × $20K 售价 = $200B 收入. 5 年内不太可能完全实现, 给 20% 概率上限
B12: AI 计算/Dojo 商业化 | C12: Cortex 2 上线 130K H100e; AI5 推理芯片 Q2 26 tape out; 与 SpaceX 共建 Research Fab | D12: 200 | E12: 0.15 | F12: =D12*E12 -> 30 | G12: 内部用为主, 若开放给外部 (类似 NVIDIA Cloud) 可能达 $30-40B/年 营收 × 6x P/S
B13: 期权组合期望值合计 | F13: =SUM(F8:F12) -> 620
B17: 二、保守调整与时间折现
B19: 保守系数（避免乐观偏差） | C19: 0.7 | D19: 默认 70%; 历史上"愿景型"业务实际达成率
B20: 5 年时间折现因子（@10%） | C20: =1/(1+0.1)^5 -> 0.62092132 | D20: 从 2031 视角折回今天 = 0.621
B21: 调整后期望值 | F21: =F13*C19*C20 -> 269.47985
B22: ⭐ 计入 SOTP 的期权价值 | F22: =F21 -> 269.47985
B25: 三、为什么 Tesla 的期权估值这么大
B26: 【对比谷歌】
B27: 谷歌：主营 ~$3,800B + 期权 ~$28B = 期权占 < 1%
B28: Tesla：主营 ~$300B + 期权 ~$300B = 期权占 ~50%
B30: 【含义】
B31: · Tesla 当前估值 60-70% 来自"还没赚到钱的业务"
B32: · 这意味着任何期权失败（特别是 Optimus 或 Robotaxi）都会让估值大跌
B33: · 也意味着任何期权超预期实现（如 FSD 完全自动化）都会大幅推升估值
B34: · Tesla 是一个"高 beta"的 AI/机器人押注, 不应该按传统汽车股估值
B36: 【监控信号】
B37: 每季度 (Sheet 7) 检查期权业务进展
B38: · Robotaxi: 月付费英里; 城市扩张数量
... B42: 若超预期 → 概率上调; 若推迟 → 概率下调

Sheet 7_AI_KPI跟踪
B2: Tesla AI/Robotics KPI 季度跟踪表
B3: 用于反向校准 Sheet 6 期权概率
B5: 一、FSD (Supervised) KPI
B7: KPI | C7: Q1 2026 | D7: Q2 2026 | E7: Q3 2026 | F7: Q4 2026 | G7: 警戒阈值 | H7: 说明
B8: 活跃订阅数 (M) | C8: 1.28 | G8: < 1.30 警戒 | H8: Q1 2026 +51% YoY; 关键变现指标
B9: 订阅 YoY 增速 | C9: +51% | G9: < 30% 警戒 | H9: 订阅速度反映 FSD 价值认知
B10: FSD 软件版本 | C10: v14.3 | G10: 迭代速度放缓警戒 | H10: v14.3 (2026/04); 期待 v15
B11: 新国家批准 | C11: 荷兰 | G11: 0 国家警戒 | H11: 2026/04 荷兰批准; 期待中国/EU
B12: 累计 FSD 英里 (B) | C12: ~10 | G12: 增速放缓警戒 | H12: 决定 RL 训练质量
B13: 每英里 disengagement | C13: n/d | G13: disengagement 上升警戒 | H13: 内部指标; 外推 unsupervised 时间
B16: 二、Robotaxi 网络 KPI
B18: KPI | C18: Q1 2026 | D18: Q2 2026 | E18: Q3 2026 | F18: Q4 2026 | G18: 警戒阈值 | H18: 说明
B19: 累计付费英里 (M) | C19: ~1.6 | G19: 环比 +30% 健康 | H19: "近翻倍" QoQ; 启动期
B20: 运营城市数 (无人) | C20: 3 (Austin/Dallas/Houston) | G20: < 5 by EOY 警戒 | H20: 已宣布 5 个准备中
B21: 运营城市数 (Safety Driver) | C21: 1 (SF Bay Area) | G21: 不要回退到 SD | H21: CA 监管限制
B22: 车队规模 | C22: n/d | G22: < 200 by Q4 警戒 | H22: 当前 Model Y 改装; 等 Cybercab 量产
B23: 单车日均订单 | C23: n/d | G23: 类比 UBER 5-8 | H23: 盈利性关键指标
B24: 收入/英里 ($) | C24: n/d | G24: < $0.8 警戒 | H24: UBER ~$1.2/英里
B27: 三、Cybercab / Semi / Megapack 3 量产 KPI
B29: 指标 | C29: Q1 2026 | D29: Q2 2026 | E29: Q3 2026 | F29: Q4 2026 | G29: 里程碑
B30: Cybercab 月生产 | C30: Pilot | G30: 2026 内量产
B31: Tesla Semi 月生产 | C31: Pilot | G31: 2026 内量产
B32: Megapack 3 量产 | C32: Pilot | G32: 2026 末
B33: 储能部署 (GWh/季) | C33: 8.8 | G33: Q2 回升至 12+ 是健康
B34: Megapack capacity (GWh) | C34: 60 | G34: Houston 工厂上线后翻倍
B37: 四、Optimus 机器人 KPI
B39: 指标 | C39: 当前 Q1 2026 | D39: 里程碑 | E39: 影响
B40: 第 1 代工厂 | C40: Fremont 准备中 (替换 S/X 线) | D40: Q2 2026 准备开始 | E40: 100 万/年产能上线后估值+
B41: 第 2 代工厂 | C41: Texas 设计中 | D41: 2027+ | E41: 1000 万/年产能, 颠覆性
B42: 首批商业客户 | C42: 无 | D42: 2026-2027 首批 | E42: 建立商业模式可信度
B43: 单台成本 | C43: n/d | D43: Musk 目标 $20K | E43: 决定能否触达消费市场
B44: 能力演示 | C44: Digital Optimus 开发中 | D44: 实物 v3 任务能力 | E44: 决定市场接受度
B47: 五、AI 基础设施 KPI
B49: 指标 | C49: Q1 2026 | D49: 目标 | E49: 战略意义
B50: AI 训练算力 (H100e) | C50: 100K (Cortex 1) + 130K (Cortex 2 ramp) | D50: 300K+ by Q4 2026 | E50: FSD/Robotaxi/Optimus 训练基础
B51: AI5 推理芯片 | C51: Tape-out 完成 (2026/04) | D51: Q3-Q4 2026 量产 | E51: 车端推理成本下降
B52: Dojo 3 | C52: 研发中 | D52: 不明 | E52: 降低长期训练成本
B53: Research Fab | C53: 破土 (与 SpaceX 共建) | D53: 2028-2030 投产 | E53: 芯片供应链垂直整合
B54: LFP 电池 | C54: Nevada 7 GWh ramp | D54: 40+ GWh 短期 | E54: 降低电池成本
B57: 六、使用方法
...

Sheet 8_概率决策框架
B2: Tesla 概率决策框架 — 扑克思维下注
B3: 原理: 不需判定真实概率, 只需判定我的估计与盈亏平衡的距离
B5: 一、核心参数（蓝色 = 你输入）
B7: 当前股价 ($) | C7: ='1_输入与假设'!C7 -> 428 | D7: 从 Sheet 1 引用
B8: 稀释股本 (B 股) | C8: ='1_输入与假设'!C8 -> 3.538 | D8: 从 Sheet 1 引用
B9: 当前市值 ($B) | C9: ='1_输入与假设'!C9 -> 1514.264 | D9: 自动 = 股价 × 股本
B10: 要求年化回报 (折现率) | C10: ='1_输入与假设'!C10 -> 0.1 | D10: 默认 10%
B11: 5 年折现因子 | C11: =(1+C10)^5 -> 1.61051 | D11: 自动 = (1+r)^5
B12: P(C 失败) 固定假设 | C12: 0.25 | D12: 可调
B13: 我的 P(A) 估计 | C13: 0.4 | D13: ⭐ 你的核心判断
B16: 二、三情景估值（蓝色 = 可调；基于之前分析）
B18: 情景 | C18: 今天公允 ($B) | D18: 今天单股 ($) | E18: 2031 公允 ($B) | F18: 2031 单股 ($) | G18: 5Y 总回报 vs 当前价
B19: A. FSD 通用化成功 | C19: 2300 | D19: =C19/$C$8 -> 650.08479 | E19: =C19*$C$11 -> 3704.173 | F19: =E19/$C$8 -> 1046.9681 | G19: =E19/$C$9-1 -> 1.4461871 | H19: SOTP Bull ($1,657B) + 期权 FSD 成功条件下 ($634B)
B20: B. 部分实现 | C20: 1100 | D20: =C20/$C$8 -> 310.91012 | E20: =C20*$C$11 -> 1771.561 | F20: =E20/$C$8 -> 500.72386 | G20: =E20/$C$9-1 -> 0.16991555 | H20: SOTP Base ($865B) + 期权 部分实现 ($224B)
B21: C. 失败 (回归汽车) | C21: 550 | D21: =C21/$C$8 -> 155.45506 | E21: =C21*$C$11 -> 885.7805 | F21: =E21/$C$8 -> 250.36193 | G21: =E21/$C$9-1 -> -0.41504223 | H21: SOTP Bear ($506B) + 期权 失败下 ($25B)
B23: ⚠️ 说明: 修订后的三情景值与 Sheet 3 SOTP 对齐(主营 + FSD 条件期权)
B24: 三、盈亏平衡分析（在当前价 $428）
B26: Break-even P(A) | C26: =(C9 - C20 + C12*(C20 - C21))/(C19 - C20) -> 0.45980333 | D26: ⭐ 当前价让 Tesla 成为 +EV 押注所需的 P(A)
B27: 我的 P(A) 估计 | C27: =C13 -> 0.4
B28: 距离盈亏平衡 (我的估计 - break-even) | C28: =C27-C26 -> -0.059803333
B29: ⭐ 决策建议 | C29: =IF(C28>=0.1,"⭐⭐ 强买入 - 明显 +EV",IF(C28>=0.05,"⭐ 买入 - +EV",IF(C28>=0,"✅ 边际买入 - 略 +EV",IF(C28>=-0.05,"⚠️ 警惕 - 接近盈亏平衡",IF(C28>=-0.15,"❌ 避免买入 - 明显 -EV","❌❌ 强避免 - 严重 -EV"))))) -> ❌ 避免买入 - 明显 -EV
B32: 四、不同 P(A) 假设下的合理价位
B33: ⭐ 这张表告诉你: 你对 FSD 多乐观 → 多少钱算公允
B35: P(A) | C35: P(B) | D35: P(C) | E35: 公允市值 ($B) | F35: 公允单股 ($) | G35: 当前价偏离 | H35: 决策建议
B36: 0.2 | C36: =1-B36-D36 -> 0.55 | D36: =$C$12 -> 0.25 | E36: =B36*$C$19 + C36*$C$20 + D36*$C$21 -> 1202.5 | F36: =E36/$C$8 -> 339.88129 | G36: =$C$9/E36-1 -> 0.2592632 | H36: =IF(B36-$C$26>=0.1,"⭐⭐ 强买入",IF(B36-$C$26>=0.05,"⭐ 买入",IF(B36-$C$26>=0,"✅ 边际买入",IF(B36-$C$26>=-0.05,"⚠️ 警惕",IF(B36-$C$26>=-0.15,"❌ 避免","❌❌ 强避免"))))) -> ❌❌ 强避免
B37: 0.25 | C37: =1-B37-D37 -> 0.5 | D37: =$C$12 -> 0.25 | E37: =B37*$C$19 + C37*$C$20 + D37*$C$21 -> 1262.5 | F37: =E37/$C$8 -> 356.84002 | G37: =$C$9/E37-1 -> 0.19941703 | H37: =IF(B37-$C$26>=0.1,"⭐⭐ 强买入",IF(B37-$C$26>=0.05,"⭐ 买入",IF(B37-$C$26>=0,"✅ 边际买入",IF(B37-$C$26>=-0.05,"⚠️ 警惕",IF(B37-$C$26>=-0.15,"❌ 避免","❌❌ 强避免"))))) -> ❌❌ 强避免
B38: 0.3 | C38: =1-B38-D38 -> 0.45 | D38: =$C$12 -> 0.25 | E38: =B38*$C$19 + C38*$C$20 + D38*$C$21 -> 1322.5 | F38: =E38/$C$8 -> 373.79876 | G38: =$C$9/E38-1 -> 0.14500113 | H38: =IF(B38-$C$26>=0.1,"⭐⭐ 强买入",IF(B38-$C$26>=0.05,"⭐ 买入",IF(B38-$C$26>=0,"✅ 边际买入",IF(B38-$C$26>=-0.05,"⚠️ 警惕",IF(B38-$C$26>=-0.15,"❌ 避免","❌❌ 强避免"))))) -> ❌❌ 强避免
B39: 0.35 | C39: =1-B39-D39 -> 0.4 | D39: =$C$12 -> 0.25 | E39: =B39*$C$19 + C39*$C$20 + D39*$C$21 -> 1382.5 | F39: =E39/$C$8 -> 390.75749 | G39: =$C$9/E39-1 -> 0.095308499 | H39: =IF(B39-$C$26>=0.1,"⭐⭐ 强买入",IF(B39-$C$26>=0.05,"⭐ 买入",IF(B39-$C$26>=0,"✅ 边际买入",IF(B39-$C$26>=-0.05,"⚠️ 警惕",IF(B39-$C$26>=-0.15,"❌ 避免","❌❌ 强避免"))))) -> ❌ 避免
B40: 0.4 | C40: =1-B40-D40 -> 0.35 | D40: =$C$12 -> 0.25 | E40: =B40*$C$19 + C40*$C$20 + D40*$C$21 -> 1442.5 | F40: =E40/$C$8 -> 407.71622 | G40: =$C$9/E40-1 -> 0.04974974 | H40: =IF(B40-$C$26>=0.1,"⭐⭐ 强买入",IF(B40-$C$26>=0.05,"⭐ 买入",IF(B40-$C$26>=0,"✅ 边际买入",IF(B40-$C$26>=-0.05,"⚠️ 警惕",IF(B40-$C$26>=-0.15,"❌ 避免","❌❌ 强避免"))))) -> ❌ 避免
B41: 0.45 | C41: =1-B41-D41 -> 0.3 | D41: =$C$12 -> 0.25 | E41: =B41*$C$19 + C41*$C$20 + D41*$C$21 -> 1502.5 | F41: =E41/$C$8 -> 424.67496 | G41: =$C$9/E41-1 -> 0.0078296173 | H41: =IF(B41-$C$26>=0.1,"⭐⭐ 强买入",IF(B41-$C$26>=0.05,"⭐ 买入",IF(B41-$C$26>=0,"✅ 边际买入",IF(B41-$C$26>=-0.05,"⚠️ 警惕",IF(B41-$C$26>=-0.15,"❌ 避免","❌❌ 强避免"))))) -> ⚠️ 警惕
B42: 0.5 | C42: =1-B42-D42 -> 0.25 | D42: =$C$12 -> 0.25 | E42: =B42*$C$19 + C42*$C$20 + D42*$C$21 -> 1562.5 | F42: =E42/$C$8 -> 441.63369 | G42: =$C$9/E42-1 -> -0.03087104 | H42: =IF(B42-$C$26>=0.1,"⭐⭐ 强买入",IF(B42-$C$26>=0.05,"⭐ 买入",IF(B42-$C$26>=0,"✅ 边际买入",IF(B42-$C$26>=-0.05,"⚠️ 警惕",IF(B42-$C$26>=-0.15,"❌ 避免","❌❌ 强避免"))))) -> ✅ 边际买入
B43: 0.55 | C43: =1-B43-D43 -> 0.2 | D43: =$C$12 -> 0.25 | E43: =B43*$C$19 + C43*$C$20 + D43*$C$21 -> 1622.5 | F43: =E43/$C$8 -> 458.59243 | G43: =$C$9/E43-1 -> -0.066709399 | H43: =IF(B43-$C$26>=0.1,"⭐⭐ 强买入",IF(B43-$C$26>=0.05,"⭐ 买入",IF(B43-$C$26>=0,"✅ 边际买入",IF(B43-$C$26>=-0.05,"⚠️ 警惕",IF(B43-$C$26>=-0.15,"❌ 避免","❌❌ 强避免"))))) -> ⭐ 买入
B44: 0.6 | C44: =1-B44-D44 -> 0.15 | D44: =$C$12 -> 0.25 | E44: =B44*$C$19 + C44*$C$20 + D44*$C$21 -> 1682.5 | F44: =E44/$C$8 -> 475.55116 | G44: =$C$9/E44-1 -> -0.099991679 | H44: =IF(B44-$C$26>=0.1,"⭐⭐ 强买入",IF(B44-$C$26>=0.05,"⭐ 买入",IF(B44-$C$26>=0,"✅ 边际买入",IF(B44-$C$26>=-0.05,"⚠️ 警惕",IF(B44-$C$26>=-0.15,"❌ 避免","❌❌ 强避免"))))) -> ⭐⭐ 强买入
B45: 0.65 | C45: =1-B45-D45 -> 0.1 | D45: =$C$12 -> 0.25 | E45: =B45*$C$19 + C45*$C$20 + D45*$C$21 -> 1742.5 | F45: =E45/$C$8 -> 492.50989 | G45: =$C$9/E45-1 -> -0.13098192 | H45: =IF(B45-$C$26>=0.1,"⭐⭐ 强买入",IF(B45-$C$26>=0.05,"⭐ 买入",IF(B45-$C$26>=0,"✅ 边际买入",IF(B45-$C$26>=-0.05,"⚠️ 警惕",IF(B45-$C$26>=-0.15,"❌ 避免","❌❌ 强避免"))))) -> ⭐⭐ 强买入
B46: 0.7 | C46: =1-B46-D46 -> 0.05 | D46: =$C$12 -> 0.25 | E46: =B46*$C$19 + C46*$C$20 + D46*$C$21 -> 1802.5 | F46: =E46/$C$8 -> 509.46863 | G46: =$C$9/E46-1 -> -0.15990902 | H46: =IF(B46-$C$26>=0.1,"⭐⭐ 强买入",IF(B46-$C$26>=0.05,"⭐ 买入",IF(B46-$C$26>=0,"✅ 边际买入",IF(B46-$C$26>=-0.05,"⚠️ 警惕",IF(B46-$C$26>=-0.15,"❌ 避免","❌❌ 强避免"))))) -> ⭐⭐ 强买入
B49: 五、不同买入价位需要的最低 P(A)（盈亏平衡）
B50: ⭐ 这张表告诉你: 在什么价位 Tesla 是合理买点（给定你的 P(A) 假设）
B52: 股价 ($) | C52: 市值 ($B) | D52: 所需 Break-even P(A) | E52: 我的估计是否够? | F52: 决策
B53: =$C$7*0.5 -> 214 | C53: =B53*$C$8 -> 757.132 | D53: =(C53-$C$20+$C$12*($C$20-$C$21))/($C$19-$C$20) -> -0.17114 | E53: =IF(D53<=$C$13-0.1,"✓✓ P(A) 远远够",IF(D53<=$C$13,"✓ P(A) 够",IF(D53<=$C$13+0.05,"⚠ P(A) 略不够","✗ P(A) 不够"))) -> ✓✓ P(A) 远远够 | F53: =IF($C$13-D53>=0.1,"⭐⭐ 强买入",IF($C$13-D53>=0.05,"⭐ 买入",IF($C$13-D53>=0,"✅ 边际买入",IF($C$13-D53>=-0.05,"⚠️ 警惕",IF($C$13-D53>=-0.15,"❌ 避免","❌❌ 强避免"))))) -> ⭐⭐ 强买入
B54: =$C$7*0.6 -> 256.8 | C54: =B54*$C$8 -> 908.5584 | D54: =(C54-$C$20+$C$12*($C$20-$C$21))/($C$19-$C$20) -> -0.044951333 | E54: =IF(D54<=$C$13-0.1,"✓✓ P(A) 远远够",IF(D54<=$C$13,"✓ P(A) 够",IF(D54<=$C$13+0.05,"⚠ P(A) 略不够","✗ P(A) 不够"))) -> ✓✓ P(A) 远远够 | F54: =IF($C$13-D54>=0.1,"⭐⭐ 强买入",IF($C$13-D54>=0.05,"⭐ 买入",IF($C$13-D54>=0,"✅ 边际买入",IF($C$13-D54>=-0.05,"⚠️ 警惕",IF($C$13-D54>=-0.15,"❌ 避免","❌❌ 强避免"))))) -> ⭐⭐ 强买入
...
